Workbook

Sheet Corners
A1: Letter Pair | B1: Case | C1: ALG | D1: COMMENTS
A2: A B | B2: ULB UFL | C2: x L U' L D2 L' U L D2 L2 x' | D2: also possible U setup for xR2[ D2;R U R' ]R2x'
A3: A C | B3: ULB UFR | C3: x R2 D2 R U R' D2 R U' R x'
A4: A E | B4: ULB DFR | C4: R' D R2 D' R' U R D R' U' R' D' R
A5: A F | B5: ULB DLF | C5: R U R' U' L2 U R U' R' L2 | D5: R D U
A6: A G | B6: ULB DBL | C6: U l' U' R D2 R' U R D2 x' U'
A7: A H | B7: ULB DRB | C7: R2 D R2 D' R2 U' R2 D R2 D' R2 U
A8: A I | B8: ULB FRU | C8: F' r U R' U' r' F R
A9: A J | B9: ULB FUL | C9: r U R' U' r' F R F'
A10: A K | B10: ULB FLD | C10: R D2 R' U R D2 R' U'
A11: A L | B11: ULB FRD | C11: U' L' D2 L U L' D2 L
A12: A O | B12: ULB BRD | C12: y R' D' R U R' D R U' y' | D12: too lazy to change it to no rotation alg in <R,U,D> (setup D, its better)
A13: A P | B13: ULB BDL | C13: U R' D2 R U R' D2 R U2
A14: A R | B14: ULB LBD | C14: R D' R' U R D R' U'
A15: A S | B15: ULB RUF | C15: U R U2 R D R' U2 R D' R2 U'
A16: A T | B16: ULB RFD | C16: U R' D' R U R' D R U2
A17: A U | B17: ULB RBD | C17: R D R' U R D' R' U'
A18: A W | B18: ULB LFU | C18: U R2 D' R U2 R' D R U2 R U'
A19: A Z | B19: ULB LDF | C19: U R' D R U R' D' R U2
A21: B A | B21: UFL ULB | C21: x L2 D2 L' U' L D2 L' U L' x'
A22: B C | B22: UFL UFR | C22: x' R U' R D2 R' U R D2 R2 x
A23: B D | B23: UFL LBU | C23: U' x R2 D2 R U2 R' D2 R U2 R x' U
A24: B E | B24: UFL DFR | C24: R' D R2 D' R' U2 R D R' U2 R' D' R
A25: B F | B25: UFL DLF | C25: R U2 R' U' L2 U R U' L2 U' R'
... A48: C K | B48: UFR FLD | C48: R D2 R' U' R D2 R' U
A49: C L | B49: UFR FRD | C49: D R D R' U' R D' R' U D' | D49: D' U R D' R' U' R D R' D
A50: C M | B50: UFR BUL | C50: R' U2 R' D' R U2 R' D R2
A51: C O | B51: UFR BRD | C51: D' U R' D' R U' R' D R D
A52: C P | B52: UFR BDL | C52: U R' D2 R U' R' D2 R
A53: C R | B53: UFR LBD | C53: R D' R U' R' D R' U
A54: C T | B54: UFR RFD | C54: U R' D' R U' R' D R
A55: C U | B55: UFR RBD | C55: R D R' U' R D' R' U
A56: C W | B56: UFR LFU | C56: R' U' R' D' R U R' D R2
A57: C Z | B57: UFR LDF | C57: U R' D R U' R' D' R
A59: D B | B59: LBU UFL | C59: U' x R2 D2 R U2 R' D2 R U2 R x' U | D59: also possible F' setup
A60: D C | B60: LBU UFR | C60: R U R D R' U' R D' R2
A61: D E | B61: LBU DFR | C61: R2 U' L' U R2 U' L U
A62: D F | B62: LBU DLF | C62: F U R U' L' U R' U' L F'
A63: D G | B63: LBU DBL | C63: L' D L' U2 L D' L' U2 L2
A64: D H | B64: LBU DRB | C64: D' R2 U' L' U R2 U' L U D
...

Sheet test
A1: Letter Pair | B1: Case | C1: ALG | D1: COMMENTS
A2: A B | B2: =tra(A2) -> ULB UFL | C2: =exc("x L2 [L' U' L;D2] L2x'") -> x L U' L D2 L' U L D2 L2 x' | D2: also possible U setup for xR2[ D2;R U R' ]R2x'
A3: A C | B3: =tra(A3) -> ULB UFR | C3: =INV(MIR(C2)) -> x R2 D2 R U R' D2 R U' R x'
A4: A E | B4: =tra(A4) -> ULB DFR | C4: =EXC("R' D R[R D' R'; U]R' D' R") -> R' D R2 D' R' U R D R' U' R' D' R
A5: A F | B5: =tra(A5) -> ULB DLF | C5: =EXC("[R U R' U';L2]") -> R U R' U' L2 U R U' R' L2 | D5: =exc("R:D4U") -> R D U
A6: A G | B6: =tra(A6) -> ULB DBL | C6: U l' U' R D2 R' U R D2 x' U'
A7: A H | B7: =tra(A7) -> ULB DRB | C7: =EXC("[R2 D R2 D' R2; U']") -> R2 D R2 D' R2 U' R2 D R2 D' R2 U | D7: =mirror("R U R'U'") -> L' U' LU
A8: A I | B8: =tra(A8) -> ULB FRU | C8: F' r U R' U' r' F R
A9: A J | B9: =tra(A9) -> ULB FUL | C9: r U R' U' r' F R F'
A10: A K | B10: =tra(A10) -> ULB FLD | C10: =EXC("[R D2 R' ; U]") -> R D2 R' U R D2 R' U'
A11: A L | B11: =tra(A11) -> ULB FRD | C11: =INV(MIR(C10)) -> U' L' D2 L U L' D2 L
A12: A O | B12: =tra(A12) -> ULB BRD | C12: =EXC("y[R' D' R; U]y'") -> y R' D' R U R' D R U' y' | D12: too lazy to change it to no rotation alg in <R,U,D> (setup D, its better)
A13: A P | B13: =tra(A13) -> ULB BDL | C13: =EXC("U2[U';R' D2 R]U2") -> U R' D2 R U R' D2 R U2
A14: A R | B14: =tra(A14) -> ULB LBD | C14: =EXC("[R D' R'; U]") -> R D' R' U R D R' U'
A15: A S | B15: =tra(A15) -> ULB RUF | C15: =EXC("U R2[R' U2 R; D]R2 U'") -> U R U2 R D R' U2 R D' R2 U'
A16: A T | B16: =tra(A16) -> ULB RFD | C16: =EXC("U2[U'; R' D' R]U2") -> U R' D' R U R' D R U2
A17: A U | B17: =tra(A17) -> ULB RBD | C17: =EXC("[R D R'; U]") -> R D R' U R D' R' U'
A18: A W | B18: =tra(A18) -> ULB LFU | C18: =EXC("U R2[D'; R U2 R']R2 U'") -> U R2 D' R U2 R' D R U2 R U'
A19: A Z | B19: =tra(A19) -> ULB LDF | C19: =EXC("U2[U'; R' D R]U2") -> U R' D R U R' D' R U2
A21: B A | B21: =tra(A21) -> UFL ULB | C21: =EXC(INV(C2)) -> x L2 D2 L' U' L D2 L' U L' x'
A22: B C | B22: =tra(A22) -> UFL UFR | C22: =EXC("x' R2 [R' U' R; D2] R2 x") -> x' R U' R D2 R' U R D2 R2 x
A23: B D | B23: =tra(A23) -> UFL LBU | C23: =EXC("U' x R2[D2; R U2 R']R2 x' U") -> U' x R2 D2 R U2 R' D2 R U2 R x' U
A24: B E | B24: =tra(A24) -> UFL DFR | C24: =EXC("R' D R[R D' R';U2]R' D' R") -> R' D R2 D' R' U2 R D R' U2 R' D' R
A25: B F | B25: =tra(A25) -> UFL DLF | C25: =EXC("R U[U R' U';L2]U' R'") -> R U2 R' U' L2 U R U' L2 U' R'
A26: B G | B26: =tra(A26) -> UFL DBL | C26: =EXC("D2 R' D R[R D' R'; U2]R' D' R D2") -> D2 R' D R2 D' R' U2 R D R' U2 R' D' R D2
A27: B H | B27: =tra(A27) -> UFL DRB | C27: =EXC("[R2 D R2 D' R2; U2]") -> R2 D R2 D' R2 U2 R2 D R2 D' R2 U2
A28: B I | B28: =tra(A28) -> UFL FRU | C28: =EXC("R D[U2;R D' R']D' R") -> R D U2 R D' R' U2 R D R' D' R
A29: B K | B29: =tra(A29) -> UFL FLD | C29: =EXC("[R D2 R';U2]") -> R D2 R' U2 R D2 R' U2
A30: B L | B30: =tra(A30) -> UFL FRD | C30: =EXC(C37) -> R D R' U2 R D' R' U2
A31: B M | B31: =tra(A31) -> UFL BUL | C31: =EXC("x' R2[R' U2 R; D2]R2 x") -> x' R U2 R D2 R' U2 R D2 R2 x
A32: B O | B32: =tra(A32) -> UFL BRD | C32: =EXC("[U2;L D2 L']") -> U2 L D2 L' U2 L D2 L'
A33: B P | B33: =tra(A33) -> UFL BDL | C33: =EXC("D' [R D R';U2] D") -> D' R D R' U2 R D' R' U2 D
A34: B R | B34: =tra(A34) -> UFL LBD | C34: =EXC("[R D R';U2]") -> R D R' U2 R D' R' U2
A35: B S | B35: =tra(A35) -> UFL RUF | C35: =EXC("U x R2 [R U2 R'; D2] R2 x' U'") -> U x R' U2 R' D2 R U2 R' D2 R2 x' U'
A36: B T | B36: =tra(A36) -> UFL RFD | C36: =EXC("U[R' D' R;U2]U'") -> U R' D' R U2 R' D R U
A37: B U | B37: =tra(A37) -> UFL RBD | C37: =EXC("[R D R'; U2]") -> R D R' U2 R D' R' U2
A38: B Z | B38: =tra(A38) -> UFL LDF | C38: =EXC("U [R' D R;U2] U'") -> U R' D R U2 R' D' R U
A40: C A | B40: =tra(A40) -> UFR ULB | C40: =EXC("x R2[R U R' ;D2]R2 x'") -> x R' U R' D2 R U' R' D2 R2 x'
A41: C B | B41: =tra(A41) -> UFR UFL | C41: =EXC("x' R2[ D2;R' U' R ]R2x") -> x' R2 D2 R' U' R D2 R' U R' x
A42: C D | B42: =tra(A42) -> UFR LBU | C42: =EXC("R2[D; R' U R]R2") -> R2 D R' U R D' R' U' R'
...
