Workbook

Sheet Info
B2: Information
B4: Hello all and welcome to my blindfolded information sheet.
B6: Here you will find all of the algorithms I use, including the following sets:
B7: - Corners
B8: - Edges
B9: - Wings
B10: - X-Centres
B11: - +-Centres
B13: Some alg sets that are missing that I plan to include at a later date are as follows:
B14: - Parity - All puzzles
B15: - Obliques (For 6BLD+)
B16: - Corners - BigBLD friendly
... B33: 2011MOLL01

Sheet Letters
B2: 3BLD
B4: Corners | C4: UBL | D4: Buffer | K4: =D5 -> B
B5: UBL Buffer | C5: UBR | D5: B
C6: UFR | D6: C | I6: =D7 -> D | K6: =D6 -> C
C7: UFL | D7: D | H7: =D9 -> F | I7: =D12 -> I | K7: =D13 -> R | L7: =D16 -> M | N7: =D17 -> N | O7: =D20 -> A
C8: LBU | D8: Buffer
C9: LFU | D9: F | F9: =D11 -> H | H9: =D10 -> G | I9: =D15 -> L | K9: =D14 -> K | L9: =D19 -> P | N9: =D18 -> O | O9: =D23 -> T | Q9: =D22 -> S
C10: LFD | D10: G | I10: =D24 -> U | K10: =D25 -> V
C11: LBD | D11: H
C12: FLU | D12: I | I12: =D27 -> E | K12: =D26 -> W
C13: FRU | D13: R
C14: FRD | D14: K
C15: FLD | D15: L
C16: RFU | D16: M
C17: RBU | D17: N
C18: RBD | D18: O
C19: RFD | D19: P
C20: BRU | D20: A
C21: BLU | D21: Buffer
C22: BLD | D22: S
C23: BRD | D23: T
C24: DFL | D24: U
... C27: DBL | D27: E
B29: Edges | C29: UF | D29: A | J29: =D31 -> C
B30: DF Buffer | C30: UL | D30: B | I30: =D30 -> B | K30: =D32 -> D
C31: UB | D31: C | J31: =D29 -> A
C32: UR | D32: D | G32: =D35 -> G | J32: =D39 -> K | M32: =D43 -> O | P32: =D47 -> S
C33: LD | D33: E | F33: =D34 -> F | H33: =D36 -> H | I33: =D38 -> J | K33: =D40 -> L | L33: =D42 -> N | N33: =D44 -> P | O33: =D46 -> R | Q33: =D48 -> T
C34: LB | D34: F | G34: =D33 -> E | M34: =D41 -> M | P34: =D45 -> W
C35: LU | D35: G
C36: LF | D36: H | I36: =D50 -> V | K36: =D52 -> I
C37: FD | D37: Buffer | J37: =D49 -> U
C38: FL | D38: J
C39: FU | D39: K
C40: FR | D40: L
C41: RD | D41: M
C42: RF | D42: N
C43: RU | D43: O
C44: RB | D44: P
C45: BD | D45: W
...

Sheet C
B2: 3-Cycles
D3: =SUM(A6:A403)&"/"&COUNTA(D6:D403) -> 196/378
B4: Target 1 | C4: Target 2 | D4: Letter Pair | E4: Commutator | F4: Algorithm | G4: HTM | H4: QTM
A6: 1 | B6: UBR | C6: UFR | D6: =VLOOKUP($B6,Letters!$C$4:$D$27,2,FALSE) & VLOOKUP($C6,Letters!$C$4:$D$27,2,FALSE) -> BC | E6: [x R': [U, R' D2 R]] | F6: Lw' U R' D2 R U' R' D2 R2 x' | G6: =(len($F6)-len(SUBSTITUTE($F6,"R","")))+(len($F6)-len(SUBSTITUTE($F6,"L","")))+(len($F6)-len(SUBSTITUTE($F6,"U","")))+(len($F6)-len(SUBSTITUTE($F6,"D","")))+(len($F6)-len(SUBSTITUTE($F6,"F","")))+(len($F6)-len(SUBSTITUTE($F6,"B",""))) -> 9 | H6: =(len($F6)-len(SUBSTITUTE($F6,"R","")))+(len($F6)-len(SUBSTITUTE($F6,"L","")))+(len($F6)-len(SUBSTITUTE($F6,"U","")))+(len($F6)-len(SUBSTITUTE($F6,"D","")))+(len($F6)-len(SUBSTITUTE($F6,"F","")))+(len($F6)-len(SUBSTITUTE($F6,"B","")))+(len($F6)-len(SUBSTITUTE($F6,"2",""))) -> 12
A7: 1 | B7: UBR | C7: UFL | D7: =VLOOKUP($B7,Letters!$C$4:$D$27,2,FALSE) & VLOOKUP($C7,Letters!$C$4:$D$27,2,FALSE) -> BD | E7: [U Lw': [U, R' D2 R]] | F7: U Lw' U R' D2 R U' R' D2 R2 x' U' | G7: =(len($F7)-len(SUBSTITUTE($F7,"R","")))+(len($F7)-len(SUBSTITUTE($F7,"L","")))+(len($F7)-len(SUBSTITUTE($F7,"U","")))+(len($F7)-len(SUBSTITUTE($F7,"D","")))+(len($F7)-len(SUBSTITUTE($F7,"F","")))+(len($F7)-len(SUBSTITUTE($F7,"B",""))) -> 11 | H7: =(len($F7)-len(SUBSTITUTE($F7,"R","")))+(len($F7)-len(SUBSTITUTE($F7,"L","")))+(len($F7)-len(SUBSTITUTE($F7,"U","")))+(len($F7)-len(SUBSTITUTE($F7,"D","")))+(len($F7)-len(SUBSTITUTE($F7,"F","")))+(len($F7)-len(SUBSTITUTE($F7,"B","")))+(len($F7)-len(SUBSTITUTE($F7,"2",""))) -> 14
A8: 1 | B8: UBR | C8: LFU | D8: =VLOOKUP($B8,Letters!$C$4:$D$27,2,FALSE) & VLOOKUP($C8,Letters!$C$4:$D$27,2,FALSE) -> BF | E8: [U R': [U2, R' D' R]] | F8: U R' U2 R' D' R U2 R' D R2 U' | G8: =(len($F8)-len(SUBSTITUTE($F8,"R","")))+(len($F8)-len(SUBSTITUTE($F8,"L","")))+(len($F8)-len(SUBSTITUTE($F8,"U","")))+(len($F8)-len(SUBSTITUTE($F8,"D","")))+(len($F8)-len(SUBSTITUTE($F8,"F","")))+(len($F8)-len(SUBSTITUTE($F8,"B",""))) -> 11 | H8: =(len($F8)-len(SUBSTITUTE($F8,"R","")))+(len($F8)-len(SUBSTITUTE($F8,"L","")))+(len($F8)-len(SUBSTITUTE($F8,"U","")))+(len($F8)-len(SUBSTITUTE($F8,"D","")))+(len($F8)-len(SUBSTITUTE($F8,"F","")))+(len($F8)-len(SUBSTITUTE($F8,"B","")))+(len($F8)-len(SUBSTITUTE($F8,"2",""))) -> 14
A9: 1 | B9: UBR | C9: LFD | D9: =VLOOKUP($B9,Letters!$C$4:$D$27,2,FALSE) & VLOOKUP($C9,Letters!$C$4:$D$27,2,FALSE) -> BG | E9: [U: [U , R' D R]] | F9: U2 R' D R U' R' D' R U' | G9: =(len($F9)-len(SUBSTITUTE($F9,"R","")))+(len($F9)-len(SUBSTITUTE($F9,"L","")))+(len($F9)-len(SUBSTITUTE($F9,"U","")))+(len($F9)-len(SUBSTITUTE($F9,"D","")))+(len($F9)-len(SUBSTITUTE($F9,"F","")))+(len($F9)-len(SUBSTITUTE($F9,"B",""))) -> 9 | H9: =(len($F9)-len(SUBSTITUTE($F9,"R","")))+(len($F9)-len(SUBSTITUTE($F9,"L","")))+(len($F9)-len(SUBSTITUTE($F9,"U","")))+(len($F9)-len(SUBSTITUTE($F9,"D","")))+(len($F9)-len(SUBSTITUTE($F9,"F","")))+(len($F9)-len(SUBSTITUTE($F9,"B","")))+(len($F9)-len(SUBSTITUTE($F9,"2",""))) -> 10
A10: 1 | B10: UBR | C10: LBD | D10: =VLOOKUP($B10,Letters!$C$4:$D$27,2,FALSE) & VLOOKUP($C10,Letters!$C$4:$D$27,2,FALSE) -> BH | E10: [U, R D' R'] | F10: U R D' R' U' R D R' | G10: =(len($F10)-len(SUBSTITUTE($F10,"R","")))+(len($F10)-len(SUBSTITUTE($F10,"L","")))+(len($F10)-len(SUBSTITUTE($F10,"U","")))+(len($F10)-len(SUBSTITUTE($F10,"D","")))+(len($F10)-len(SUBSTITUTE($F10,"F","")))+(len($F10)-len(SUBSTITUTE($F10,"B",""))) -> 8 | H10: =(len($F10)-len(SUBSTITUTE($F10,"R","")))+(len($F10)-len(SUBSTITUTE($F10,"L","")))+(len($F10)-len(SUBSTITUTE($F10,"U","")))+(len($F10)-len(SUBSTITUTE($F10,"D","")))+(len($F10)-len(SUBSTITUTE($F10,"F","")))+(len($F10)-len(SUBSTITUTE($F10,"B","")))+(len($F10)-len(SUBSTITUTE($F10,"2",""))) -> 8
A11: 1 | B11: UBR | C11: FLU | D11: =VLOOKUP($B11,Letters!$C$4:$D$27,2,FALSE) & VLOOKUP($C11,Letters!$C$4:$D$27,2,FALSE) -> BI | E11: [F R' F' , L] | F11: F R' F' Rw U R U' Rw' | G11: =(len($F11)-len(SUBSTITUTE($F11,"R","")))+(len($F11)-len(SUBSTITUTE($F11,"L","")))+(len($F11)-len(SUBSTITUTE($F11,"U","")))+(len($F11)-len(SUBSTITUTE($F11,"D","")))+(len($F11)-len(SUBSTITUTE($F11,"F","")))+(len($F11)-len(SUBSTITUTE($F11,"B",""))) -> 8 | H11: =(len($F11)-len(SUBSTITUTE($F11,"R","")))+(len($F11)-len(SUBSTITUTE($F11,"L","")))+(len($F11)-len(SUBSTITUTE($F11,"U","")))+(len($F11)-len(SUBSTITUTE($F11,"D","")))+(len($F11)-len(SUBSTITUTE($F11,"F","")))+(len($F11)-len(SUBSTITUTE($F11,"B","")))+(len($F11)-len(SUBSTITUTE($F11,"2",""))) -> 8
A12: 1 | B12: UBR | C12: FRU | D12: =VLOOKUP($B12,Letters!$C$4:$D$27,2,FALSE) & VLOOKUP($C12,Letters!$C$4:$D$27,2,FALSE) -> BR | E12: [U R': [U', R' D' R]] | F12: U R' U' R' D' R U R' D R2 U' | G12: =(len($F12)-len(SUBSTITUTE($F12,"R","")))+(len($F12)-len(SUBSTITUTE($F12,"L","")))+(len($F12)-len(SUBSTITUTE($F12,"U","")))+(len($F12)-len(SUBSTITUTE($F12,"D","")))+(len($F12)-len(SUBSTITUTE($F12,"F","")))+(len($F12)-len(SUBSTITUTE($F12,"B",""))) -> 11 | H12: =(len($F12)-len(SUBSTITUTE($F12,"R","")))+(len($F12)-len(SUBSTITUTE($F12,"L","")))+(len($F12)-len(SUBSTITUTE($F12,"U","")))+(len($F12)-len(SUBSTITUTE($F12,"D","")))+(len($F12)-len(SUBSTITUTE($F12,"F","")))+(len($F12)-len(SUBSTITUTE($F12,"B","")))+(len($F12)-len(SUBSTITUTE($F12,"2",""))) -> 12
A13: 1 | B13: UBR | C13: FRD | D13: =VLOOKUP($B13,Letters!$C$4:$D$27,2,FALSE) & VLOOKUP($C13,Letters!$C$4:$D$27,2,FALSE) -> BK | E13: [U D': [U, R' D R]] | F13: U2 D' R' D R U' R' D' R D U' | G13: =(len($F13)-len(SUBSTITUTE($F13,"R","")))+(len($F13)-len(SUBSTITUTE($F13,"L","")))+(len($F13)-len(SUBSTITUTE($F13,"U","")))+(len($F13)-len(SUBSTITUTE($F13,"D","")))+(len($F13)-len(SUBSTITUTE($F13,"F","")))+(len($F13)-len(SUBSTITUTE($F13,"B",""))) -> 11 | H13: =(len($F13)-len(SUBSTITUTE($F13,"R","")))+(len($F13)-len(SUBSTITUTE($F13,"L","")))+(len($F13)-len(SUBSTITUTE($F13,"U","")))+(len($F13)-len(SUBSTITUTE($F13,"D","")))+(len($F13)-len(SUBSTITUTE($F13,"F","")))+(len($F13)-len(SUBSTITUTE($F13,"B","")))+(len($F13)-len(SUBSTITUTE($F13,"2",""))) -> 12
A14: 1 | B14: UBR | C14: FLD | D14: =VLOOKUP($B14,Letters!$C$4:$D$27,2,FALSE) & VLOOKUP($C14,Letters!$C$4:$D$27,2,FALSE) -> BL | E14: [U, R D2 R'] | F14: U R D2 R' U' R D2 R' | G14: =(len($F14)-len(SUBSTITUTE($F14,"R","")))+(len($F14)-len(SUBSTITUTE($F14,"L","")))+(len($F14)-len(SUBSTITUTE($F14,"U","")))+(len($F14)-len(SUBSTITUTE($F14,"D","")))+(len($F14)-len(SUBSTITUTE($F14,"F","")))+(len($F14)-len(SUBSTITUTE($F14,"B",""))) -> 8 | H14: =(len($F14)-len(SUBSTITUTE($F14,"R","")))+(len($F14)-len(SUBSTITUTE($F14,"L","")))+(len($F14)-len(SUBSTITUTE($F14,"U","")))+(len($F14)-len(SUBSTITUTE($F14,"D","")))+(len($F14)-len(SUBSTITUTE($F14,"F","")))+(len($F14)-len(SUBSTITUTE($F14,"B","")))+(len($F14)-len(SUBSTITUTE($F14,"2",""))) -> 10
A15: 1 | B15: UBR | C15: RFU | D15: =VLOOKUP($B15,Letters!$C$4:$D$27,2,FALSE) & VLOOKUP($C15,Letters!$C$4:$D$27,2,FALSE) -> BM | E15: [U R: [R D R', U2]] | F15: U R2 D R' U2 R D' R' U2 R' U' | G15: =(len($F15)-len(SUBSTITUTE($F15,"R","")))+(len($F15)-len(SUBSTITUTE($F15,"L","")))+(len($F15)-len(SUBSTITUTE($F15,"U","")))+(len($F15)-len(SUBSTITUTE($F15,"D","")))+(len($F15)-len(SUBSTITUTE($F15,"F","")))+(len($F15)-len(SUBSTITUTE($F15,"B",""))) -> 11 | H15: =(len($F15)-len(SUBSTITUTE($F15,"R","")))+(len($F15)-len(SUBSTITUTE($F15,"L","")))+(len($F15)-len(SUBSTITUTE($F15,"U","")))+(len($F15)-len(SUBSTITUTE($F15,"D","")))+(len($F15)-len(SUBSTITUTE($F15,"F","")))+(len($F15)-len(SUBSTITUTE($F15,"B","")))+(len($F15)-len(SUBSTITUTE($F15,"2",""))) -> 14
A16: 1 | B16: UBR | C16: RBD | D16: =VLOOKUP($B16,Letters!$C$4:$D$27,2,FALSE) & VLOOKUP($C16,Letters!$C$4:$D$27,2,FALSE) -> BO | E16: [U, R D R'] | F16: U R D R' U' R D' R' | G16: =(len($F16)-len(SUBSTITUTE($F16,"R","")))+(len($F16)-len(SUBSTITUTE($F16,"L","")))+(len($F16)-len(SUBSTITUTE($F16,"U","")))+(len($F16)-len(SUBSTITUTE($F16,"D","")))+(len($F16)-len(SUBSTITUTE($F16,"F","")))+(len($F16)-len(SUBSTITUTE($F16,"B",""))) -> 8 | H16: =(len($F16)-len(SUBSTITUTE($F16,"R","")))+(len($F16)-len(SUBSTITUTE($F16,"L","")))+(len($F16)-len(SUBSTITUTE($F16,"U","")))+(len($F16)-len(SUBSTITUTE($F16,"D","")))+(len($F16)-len(SUBSTITUTE($F16,"F","")))+(len($F16)-len(SUBSTITUTE($F16,"B","")))+(len($F16)-len(SUBSTITUTE($F16,"2",""))) -> 8
A17: 1 | B17: UBR | C17: RFD | D17: =VLOOKUP($B17,Letters!$C$4:$D$27,2,FALSE) & VLOOKUP($C17,Letters!$C$4:$D$27,2,FALSE) -> BP | E17: [U: [U, R' D' R]] | F17: U2 R' D' R U' R' D R U' | G17: =(len($F17)-len(SUBSTITUTE($F17,"R","")))+(len($F17)-len(SUBSTITUTE($F17,"L","")))+(len($F17)-len(SUBSTITUTE($F17,"U","")))+(len($F17)-len(SUBSTITUTE($F17,"D","")))+(len($F17)-len(SUBSTITUTE($F17,"F","")))+(len($F17)-len(SUBSTITUTE($F17,"B",""))) -> 9 | H17: =(len($F17)-len(SUBSTITUTE($F17,"R","")))+(len($F17)-len(SUBSTITUTE($F17,"L","")))+(len($F17)-len(SUBSTITUTE($F17,"U","")))+(len($F17)-len(SUBSTITUTE($F17,"D","")))+(len($F17)-len(SUBSTITUTE($F17,"F","")))+(len($F17)-len(SUBSTITUTE($F17,"B","")))+(len($F17)-len(SUBSTITUTE($F17,"2",""))) -> 10
... A22: 1 | B22: UBR | C22: DBR | D22: =VLOOKUP($B22,Letters!$C$4:$D$27,2,FALSE) & VLOOKUP($C22,Letters!$C$4:$D$27,2,FALSE) -> BW | E22: [U, R2 D R2 D' R2] | F22: U R2 D R2 D' R2 U' R2 D R2 D' R2 | G22: =(len($F22)-len(SUBSTITUTE($F22,"R","")))+(len($F22)-len(SUBSTITUTE($F22,"L","")))+(len($F22)-len(SUBSTITUTE($F22,"U","")))+(len($F22)-len(SUBSTITUTE($F22,"D","")))+(len($F22)-len(SUBSTITUTE($F22,"F","")))+(len($F22)-len(SUBSTITUTE($F22,"B",""))) -> 12 | H22: =(len($F22)-len(SUBSTITUTE($F22,"R","")))+(len($F22)-len(SUBSTITUTE($F22,"L","")))+(len($F22)-len(SUBSTITUTE($F22,"U","")))+(len($F22)-len(SUBSTITUTE($F22,"D","")))+(len($F22)-len(SUBSTITUTE($F22,"F","")))+(len($F22)-len(SUBSTITUTE($F22,"B","")))+(len($F22)-len(SUBSTITUTE($F22,"2",""))) -> 18
A23: 1 | B23: UBR | C23: DBL | D23: =VLOOKUP($B23,Letters!$C$4:$D$27,2,FALSE) & VLOOKUP($C23,Letters!$C$4:$D$27,2,FALSE) -> BE | E23: [U: [B2, U' R U R']] | F23: U B2 U' R U R' B2 R U' R' | G23: =(len($F23)-len(SUBSTITUTE($F23,"R","")))+(len($F23)-len(SUBSTITUTE($F23,"L","")))+(len($F23)-len(SUBSTITUTE($F23,"U","")))+(len($F23)-len(SUBSTITUTE($F23,"D","")))+(len($F23)-len(SUBSTITUTE($F23,"F","")))+(len($F23)-len(SUBSTITUTE($F23,"B",""))) -> 10 | H23: =(len($F23)-len(SUBSTITUTE($F23,"R","")))+(len($F23)-len(SUBSTITUTE($F23,"L","")))+(len($F23)-len(SUBSTITUTE($F23,"U","")))+(len($F23)-len(SUBSTITUTE($F23,"D","")))+(len($F23)-len(SUBSTITUTE($F23,"F","")))+(len($F23)-len(SUBSTITUTE($F23,"B","")))+(len($F23)-len(SUBSTITUTE($F23,"2",""))) -> 12 | I23: =AVERAGE($H6:$H23) -> 11.444444
A25: 1 | B25: UFR | C25: UBR | D25: =VLOOKUP($B25,Letters!$C$4:$D$27,2,FALSE) & VLOOKUP($C25,Letters!$C$4:$D$27,2,FALSE) -> CB | E25: [Lw': [R' D2 R, U]] | F25: x R2 D2 R U R' D2 R U' Lw | G25: =(len($F25)-len(SUBSTITUTE($F25,"R","")))+(len($F25)-len(SUBSTITUTE($F25,"L","")))+(len($F25)-len(SUBSTITUTE($F25,"U","")))+(len($F25)-len(SUBSTITUTE($F25,"D","")))+(len($F25)-len(SUBSTITUTE($F25,"F","")))+(len($F25)-len(SUBSTITUTE($F25,"B",""))) -> 9 | H25: =(len($F25)-len(SUBSTITUTE($F25,"R","")))+(len($F25)-len(SUBSTITUTE($F25,"L","")))+(len($F25)-len(SUBSTITUTE($F25,"U","")))+(len($F25)-len(SUBSTITUTE($F25,"D","")))+(len($F25)-len(SUBSTITUTE($F25,"F","")))+(len($F25)-len(SUBSTITUTE($F25,"B","")))+(len($F25)-len(SUBSTITUTE($F25,"2",""))) -> 12
A26: 1 | B26: UFR | C26: UFL | D26: =VLOOKUP($B26,Letters!$C$4:$D$27,2,FALSE) & VLOOKUP($C26,Letters!$C$4:$D$27,2,FALSE) -> CD | E26: [R' D' U': [R' D R, U']] | F26: R' D' U' R' D R U' R' D' R U2 D R | G26: =(len($F26)-len(SUBSTITUTE($F26,"R","")))+(len($F26)-len(SUBSTITUTE($F26,"L","")))+(len($F26)-len(SUBSTITUTE($F26,"U","")))+(len($F26)-len(SUBSTITUTE($F26,"D","")))+(len($F26)-len(SUBSTITUTE($F26,"F","")))+(len($F26)-len(SUBSTITUTE($F26,"B",""))) -> 13 | H26: =(len($F26)-len(SUBSTITUTE($F26,"R","")))+(len($F26)-len(SUBSTITUTE($F26,"L","")))+(len($F26)-len(SUBSTITUTE($F26,"U","")))+(len($F26)-len(SUBSTITUTE($F26,"D","")))+(len($F26)-len(SUBSTITUTE($F26,"F","")))+(len($F26)-len(SUBSTITUTE($F26,"B","")))+(len($F26)-len(SUBSTITUTE($F26,"2",""))) -> 14
B27: UFR | C27: LFU | D27: =VLOOKUP($B27,Letters!$C$4:$D$27,2,FALSE) & VLOOKUP($C27,Letters!$C$4:$D$27,2,FALSE) -> CF | E27: [R' U' D' R U': [U2, R' D R]] | F27: R' U' D' R U R' D R U2 R' D' R U R' D U R | G27: =(len($F27)-len(SUBSTITUTE($F27,"R","")))+(len($F27)-len(SUBSTITUTE($F27,"L","")))+(len($F27)-len(SUBSTITUTE($F27,"U","")))+(len($F27)-len(SUBSTITUTE($F27,"D","")))+(len($F27)-len(SUBSTITUTE($F27,"F","")))+(len($F27)-len(SUBSTITUTE($F27,"B",""))) -> 17 | H27: =(len($F27)-len(SUBSTITUTE($F27,"R","")))+(len($F27)-len(SUBSTITUTE($F27,"L","")))+(len($F27)-len(SUBSTITUTE($F27,"U","")))+(len($F27)-len(SUBSTITUTE($F27,"D","")))+(len($F27)-len(SUBSTITUTE($F27,"F","")))+(len($F27)-len(SUBSTITUTE($F27,"B","")))+(len($F27)-len(SUBSTITUTE($F27,"2",""))) -> 18
A28: 1 | B28: UFR | C28: LFD | D28: =VLOOKUP($B28,Letters!$C$4:$D$27,2,FALSE) & VLOOKUP($C28,Letters!$C$4:$D$27,2,FALSE) -> CG | E28: [U2, R' D R] | F28: U2 R' D R U2 R' D' R | G28: =(len($F28)-len(SUBSTITUTE($F28,"R","")))+(len($F28)-len(SUBSTITUTE($F28,"L","")))+(len($F28)-len(SUBSTITUTE($F28,"U","")))+(len($F28)-len(SUBSTITUTE($F28,"D","")))+(len($F28)-len(SUBSTITUTE($F28,"F","")))+(len($F28)-len(SUBSTITUTE($F28,"B",""))) -> 8 | H28: =(len($F28)-len(SUBSTITUTE($F28,"R","")))+(len($F28)-len(SUBSTITUTE($F28,"L","")))+(len($F28)-len(SUBSTITUTE($F28,"U","")))+(len($F28)-len(SUBSTITUTE($F28,"D","")))+(len($F28)-len(SUBSTITUTE($F28,"F","")))+(len($F28)-len(SUBSTITUTE($F28,"B","")))+(len($F28)-len(SUBSTITUTE($F28,"2",""))) -> 10
A29: 1 | B29: UFR | C29: LBD | D29: =VLOOKUP($B29,Letters!$C$4:$D$27,2,FALSE) & VLOOKUP($C29,Letters!$C$4:$D$27,2,FALSE) -> CH | E29: [U': [U2, R D' R']] | F29: U R D' R' U2 R D R' U | G29: =(len($F29)-len(SUBSTITUTE($F29,"R","")))+(len($F29)-len(SUBSTITUTE($F29,"L","")))+(len($F29)-len(SUBSTITUTE($F29,"U","")))+(len($F29)-len(SUBSTITUTE($F29,"D","")))+(len($F29)-len(SUBSTITUTE($F29,"F","")))+(len($F29)-len(SUBSTITUTE($F29,"B",""))) -> 9 | H29: =(len($F29)-len(SUBSTITUTE($F29,"R","")))+(len($F29)-len(SUBSTITUTE($F29,"L","")))+(len($F29)-len(SUBSTITUTE($F29,"U","")))+(len($F29)-len(SUBSTITUTE($F29,"D","")))+(len($F29)-len(SUBSTITUTE($F29,"F","")))+(len($F29)-len(SUBSTITUTE($F29,"B","")))+(len($F29)-len(SUBSTITUTE($F29,"2",""))) -> 10
B30: UFR | C30: FLU | D30: =VLOOKUP($B30,Letters!$C$4:$D$27,2,FALSE) & VLOOKUP($C30,Letters!$C$4:$D$27,2,FALSE) -> CI | E30: [Lw' U' D': [R D R', U2]] | F30: Lw' U' D' R D R' U2 R D' R' U' D Lw | G30: =(len($F30)-len(SUBSTITUTE($F30,"R","")))+(len($F30)-len(SUBSTITUTE($F30,"L","")))+(len($F30)-len(SUBSTITUTE($F30,"U","")))+(len($F30)-len(SUBSTITUTE($F30,"D","")))+(len($F30)-len(SUBSTITUTE($F30,"F","")))+(len($F30)-len(SUBSTITUTE($F30,"B",""))) -> 13 | H30: =(len($F30)-len(SUBSTITUTE($F30,"R","")))+(len($F30)-len(SUBSTITUTE($F30,"L","")))+(len($F30)-len(SUBSTITUTE($F30,"U","")))+(len($F30)-len(SUBSTITUTE($F30,"D","")))+(len($F30)-len(SUBSTITUTE($F30,"F","")))+(len($F30)-len(SUBSTITUTE($F30,"B","")))+(len($F30)-len(SUBSTITUTE($F30,"2",""))) -> 14
A31: 1 | B31: UFR | C31: FRD | D31: =VLOOKUP($B31,Letters!$C$4:$D$27,2,FALSE) & VLOOKUP($C31,Letters!$C$4:$D$27,2,FALSE) -> CK | E31: [D': [U2, R' D R]] | F31: D' U2 R' D R U2 R' D' R D | G31: =(len($F31)-len(SUBSTITUTE($F31,"R","")))+(len($F31)-len(SUBSTITUTE($F31,"L","")))+(len($F31)-len(SUBSTITUTE($F31,"U","")))+(len($F31)-len(SUBSTITUTE($F31,"D","")))+(len($F31)-len(SUBSTITUTE($F31,"F","")))+(len($F31)-len(SUBSTITUTE($F31,"B",""))) -> 10 | H31: =(len($F31)-len(SUBSTITUTE($F31,"R","")))+(len($F31)-len(SUBSTITUTE($F31,"L","")))+(len($F31)-len(SUBSTITUTE($F31,"U","")))+(len($F31)-len(SUBSTITUTE($F31,"D","")))+(len($F31)-len(SUBSTITUTE($F31,"F","")))+(len($F31)-len(SUBSTITUTE($F31,"B","")))+(len($F31)-len(SUBSTITUTE($F31,"2",""))) -> 12
A32: 1 | B32: UFR | C32: FLD | D32: =VLOOKUP($B32,Letters!$C$4:$D$27,2,FALSE) & VLOOKUP($C32,Letters!$C$4:$D$27,2,FALSE) -> CL | E32: [D: [U2, R' D' R]] | F32: D U2 R' D' R U2 R' D R D' | G32: =(len($F32)-len(SUBSTITUTE($F32,"R","")))+(len($F32)-len(SUBSTITUTE($F32,"L","")))+(len($F32)-len(SUBSTITUTE($F32,"U","")))+(len($F32)-len(SUBSTITUTE($F32,"D","")))+(len($F32)-len(SUBSTITUTE($F32,"F","")))+(len($F32)-len(SUBSTITUTE($F32,"B",""))) -> 10 | H32: =(len($F32)-len(SUBSTITUTE($F32,"R","")))+(len($F32)-len(SUBSTITUTE($F32,"L","")))+(len($F32)-len(SUBSTITUTE($F32,"U","")))+(len($F32)-len(SUBSTITUTE($F32,"D","")))+(len($F32)-len(SUBSTITUTE($F32,"F","")))+(len($F32)-len(SUBSTITUTE($F32,"B","")))+(len($F32)-len(SUBSTITUTE($F32,"2",""))) -> 12
A33: 1 | B33: UFR | C33: RBU | D33: =VLOOKUP($B33,Letters!$C$4:$D$27,2,FALSE) & VLOOKUP($C33,Letters!$C$4:$D$27,2,FALSE) -> CN | E33: [R' U D R: [D', R U' R']] | F33: R' U D R D' R U' R' D R U R2 D' U' R | G33: =(len($F33)-len(SUBSTITUTE($F33,"R","")))+(len($F33)-len(SUBSTITUTE($F33,"L","")))+(len($F33)-len(SUBSTITUTE($F33,"U","")))+(len($F33)-len(SUBSTITUTE($F33,"D","")))+(len($F33)-len(SUBSTITUTE($F33,"F","")))+(len($F33)-len(SUBSTITUTE($F33,"B",""))) -> 15 | H33: =(len($F33)-len(SUBSTITUTE($F33,"R","")))+(len($F33)-len(SUBSTITUTE($F33,"L","")))+(len($F33)-len(SUBSTITUTE($F33,"U","")))+(len($F33)-len(SUBSTITUTE($F33,"D","")))+(len($F33)-len(SUBSTITUTE($F33,"F","")))+(len($F33)-len(SUBSTITUTE($F33,"B","")))+(len($F33)-len(SUBSTITUTE($F33,"2",""))) -> 16
A34: 1 | B34: UFR | C34: RBD | D34: =VLOOKUP($B34,Letters!$C$4:$D$27,2,FALSE) & VLOOKUP($C34,Letters!$C$4:$D$27,2,FALSE) -> CO | E34: [U': [U2, R D R']] | F34: U R D R' U2 R D' R' U | G34: =(len($F34)-len(SUBSTITUTE($F34,"R","")))+(len($F34)-len(SUBSTITUTE($F34,"L","")))+(len($F34)-len(SUBSTITUTE($F34,"U","")))+(len($F34)-len(SUBSTITUTE($F34,"D","")))+(len($F34)-len(SUBSTITUTE($F34,"F","")))+(len($F34)-len(SUBSTITUTE($F34,"B",""))) -> 9 | H34: =(len($F34)-len(SUBSTITUTE($F34,"R","")))+(len($F34)-len(SUBSTITUTE($F34,"L","")))+(len($F34)-len(SUBSTITUTE($F34,"U","")))+(len($F34)-len(SUBSTITUTE($F34,"D","")))+(len($F34)-len(SUBSTITUTE($F34,"F","")))+(len($F34)-len(SUBSTITUTE($F34,"B","")))+(len($F34)-len(SUBSTITUTE($F34,"2",""))) -> 10
A35: 1 | B35: UFR | C35: RFD | D35: =VLOOKUP($B35,Letters!$C$4:$D$27,2,FALSE) & VLOOKUP($C35,Letters!$C$4:$D$27,2,FALSE) -> CP | E35: [U2, R' D' R] | F35: U2 R' D' R U2 R' D R | G35: =(len($F35)-len(SUBSTITUTE($F35,"R","")))+(len($F35)-len(SUBSTITUTE($F35,"L","")))+(len($F35)-len(SUBSTITUTE($F35,"U","")))+(len($F35)-len(SUBSTITUTE($F35,"D","")))+(len($F35)-len(SUBSTITUTE($F35,"F","")))+(len($F35)-len(SUBSTITUTE($F35,"B",""))) -> 8 | H35: =(len($F35)-len(SUBSTITUTE($F35,"R","")))+(len($F35)-len(SUBSTITUTE($F35,"L","")))+(len($F35)-len(SUBSTITUTE($F35,"U","")))+(len($F35)-len(SUBSTITUTE($F35,"D","")))+(len($F35)-len(SUBSTITUTE($F35,"F","")))+(len($F35)-len(SUBSTITUTE($F35,"B","")))+(len($F35)-len(SUBSTITUTE($F35,"2",""))) -> 10
A36: 1 | B36: UFR | C36: BRU | D36: =VLOOKUP($B36,Letters!$C$4:$D$27,2,FALSE) & VLOOKUP($C36,Letters!$C$4:$D$27,2,FALSE) -> CA | E36: [R' D': [R' D R, U2]] | F36: R' D' R' D R U2 R' D' R U2 D R | G36: =(len($F36)-len(SUBSTITUTE($F36,"R","")))+(len($F36)-len(SUBSTITUTE($F36,"L","")))+(len($F36)-len(SUBSTITUTE($F36,"U","")))+(len($F36)-len(SUBSTITUTE($F36,"D","")))+(len($F36)-len(SUBSTITUTE($F36,"F","")))+(len($F36)-len(SUBSTITUTE($F36,"B",""))) -> 12 | H36: =(len($F36)-len(SUBSTITUTE($F36,"R","")))+(len($F36)-len(SUBSTITUTE($F36,"L","")))+(len($F36)-len(SUBSTITUTE($F36,"U","")))+(len($F36)-len(SUBSTITUTE($F36,"D","")))+(len($F36)-len(SUBSTITUTE($F36,"F","")))+(len($F36)-len(SUBSTITUTE($F36,"B","")))+(len($F36)-len(SUBSTITUTE($F36,"2",""))) -> 14
B37: UFR | C37: BLD | D37: =VLOOKUP($B37,Letters!$C$4:$D$27,2,FALSE) & VLOOKUP($C37,Letters!$C$4:$D$27,2,FALSE) -> CS | E37: [U D': [R D R', U2]] | F37: U D' R D R' U2 R D' R' D U | G37: =(len($F37)-len(SUBSTITUTE($F37,"R","")))+(len($F37)-len(SUBSTITUTE($F37,"L","")))+(len($F37)-len(SUBSTITUTE($F37,"U","")))+(len($F37)-len(SUBSTITUTE($F37,"D","")))+(len($F37)-len(SUBSTITUTE($F37,"F","")))+(len($F37)-len(SUBSTITUTE($F37,"B",""))) -> 11 | H37: =(len($F37)-len(SUBSTITUTE($F37,"R","")))+(len($F37)-len(SUBSTITUTE($F37,"L","")))+(len($F37)-len(SUBSTITUTE($F37,"U","")))+(len($F37)-len(SUBSTITUTE($F37,"D","")))+(len($F37)-len(SUBSTITUTE($F37,"F","")))+(len($F37)-len(SUBSTITUTE($F37,"B","")))+(len($F37)-len(SUBSTITUTE($F37,"2",""))) -> 12
B38: UFR | C38: BRD | D38: =VLOOKUP($B38,Letters!$C$4:$D$27,2,FALSE) & VLOOKUP($C38,Letters!$C$4:$D$27,2,FALSE) -> CT | E38: [D U: [R D' R', U2]] | F38: D U R D' R' U2 R D R' U D' | G38: =(len($F38)-len(SUBSTITUTE($F38,"R","")))+(len($F38)-len(SUBSTITUTE($F38,"L","")))+(len($F38)-len(SUBSTITUTE($F38,"U","")))+(len($F38)-len(SUBSTITUTE($F38,"D","")))+(len($F38)-len(SUBSTITUTE($F38,"F","")))+(len($F38)-len(SUBSTITUTE($F38,"B",""))) -> 11 | H38: =(len($F38)-len(SUBSTITUTE($F38,"R","")))+(len($F38)-len(SUBSTITUTE($F38,"L","")))+(len($F38)-len(SUBSTITUTE($F38,"U","")))+(len($F38)-len(SUBSTITUTE($F38,"D","")))+(len($F38)-len(SUBSTITUTE($F38,"F","")))+(len($F38)-len(SUBSTITUTE($F38,"B","")))+(len($F38)-len(SUBSTITUTE($F38,"2",""))) -> 12
A39: 1 | B39: UFR | C39: DFL | D39: =VLOOKUP($B39,Letters!$C$4:$D$27,2,FALSE) & VLOOKUP($C39,Letters!$C$4:$D$27,2,FALSE) -> CU | E39: [R D R' D U: [R D' R', U2]] | F39: R D R' D U R D' R' U2 R D R' U D' R D' R' | G39: =(len($F39)-len(SUBSTITUTE($F39,"R","")))+(len($F39)-len(SUBSTITUTE($F39,"L","")))+(len($F39)-len(SUBSTITUTE($F39,"U","")))+(len($F39)-len(SUBSTITUTE($F39,"D","")))+(len($F39)-len(SUBSTITUTE($F39,"F","")))+(len($F39)-len(SUBSTITUTE($F39,"B",""))) -> 17 | H39: =(len($F39)-len(SUBSTITUTE($F39,"R","")))+(len($F39)-len(SUBSTITUTE($F39,"L","")))+(len($F39)-len(SUBSTITUTE($F39,"U","")))+(len($F39)-len(SUBSTITUTE($F39,"D","")))+(len($F39)-len(SUBSTITUTE($F39,"F","")))+(len($F39)-len(SUBSTITUTE($F39,"B","")))+(len($F39)-len(SUBSTITUTE($F39,"2",""))) -> 18
B40: UFR | C40: DFR | D40: =VLOOKUP($B40,Letters!$C$4:$D$27,2,FALSE) & VLOOKUP($C40,Letters!$C$4:$D$27,2,FALSE) -> CV | E40: [R2: [R2 D R2 D' R2, U]] | F40: D R2 D' R2 U R2 D R2 D' R2 U' R2 | G40: =(len($F40)-len(SUBSTITUTE($F40,"R","")))+(len($F40)-len(SUBSTITUTE($F40,"L","")))+(len($F40)-len(SUBSTITUTE($F40,"U","")))+(len($F40)-len(SUBSTITUTE($F40,"D","")))+(len($F40)-len(SUBSTITUTE($F40,"F","")))+(len($F40)-len(SUBSTITUTE($F40,"B",""))) -> 12 | H40: =(len($F40)-len(SUBSTITUTE($F40,"R","")))+(len($F40)-len(SUBSTITUTE($F40,"L","")))+(len($F40)-len(SUBSTITUTE($F40,"U","")))+(len($F40)-len(SUBSTITUTE($F40,"D","")))+(len($F40)-len(SUBSTITUTE($F40,"F","")))+(len($F40)-len(SUBSTITUTE($F40,"B","")))+(len($F40)-len(SUBSTITUTE($F40,"2",""))) -> 18
B41: UFR | C41: DBR | D41: =VLOOKUP($B41,Letters!$C$4:$D$27,2,FALSE) & VLOOKUP($C41,Letters!$C$4:$D$27,2,FALSE) -> CW | E41: [R D' R': [U2, R' D R]] | F41: R D' R' U2 R' D R U2 R' D' R2 D R' | G41: =(len($F41)-len(SUBSTITUTE($F41,"R","")))+(len($F41)-len(SUBSTITUTE($F41,"L","")))+(len($F41)-len(SUBSTITUTE($F41,"U","")))+(len($F41)-len(SUBSTITUTE($F41,"D","")))+(len($F41)-len(SUBSTITUTE($F41,"F","")))+(len($F41)-len(SUBSTITUTE($F41,"B",""))) -> 13 | H41: =(len($F41)-len(SUBSTITUTE($F41,"R","")))+(len($F41)-len(SUBSTITUTE($F41,"L","")))+(len($F41)-len(SUBSTITUTE($F41,"U","")))+(len($F41)-len(SUBSTITUTE($F41,"D","")))+(len($F41)-len(SUBSTITUTE($F41,"F","")))+(len($F41)-len(SUBSTITUTE($F41,"B","")))+(len($F41)-len(SUBSTITUTE($F41,"2",""))) -> 16
B42: UFR | C42: DBL | D42: =VLOOKUP($B42,Letters!$C$4:$D$27,2,FALSE) & VLOOKUP($C42,Letters!$C$4:$D$27,2,FALSE) -> CE | E42: [R' U' D' R: [D, R U' R']] | F42: R' U' D' R D R U' R' D' R U R2 D U R | G42: =(len($F42)-len(SUBSTITUTE($F42,"R","")))+(len($F42)-len(SUBSTITUTE($F42,"L","")))+(len($F42)-len(SUBSTITUTE($F42,"U","")))+(len($F42)-len(SUBSTITUTE($F42,"D","")))+(len($F42)-len(SUBSTITUTE($F42,"F","")))+(len($F42)-len(SUBSTITUTE($F42,"B",""))) -> 15 | H42: =(len($F42)-len(SUBSTITUTE($F42,"R","")))+(len($F42)-len(SUBSTITUTE($F42,"L","")))+(len($F42)-len(SUBSTITUTE($F42,"U","")))+(len($F42)-len(SUBSTITUTE($F42,"D","")))+(len($F42)-len(SUBSTITUTE($F42,"F","")))+(len($F42)-len(SUBSTITUTE($F42,"B","")))+(len($F42)-len(SUBSTITUTE($F42,"2",""))) -> 16 | I42: =AVERAGE($H25:$H42) -> 13.555556
A44: 1 | B44: UFL | C44: UBR | D44: =VLOOKUP($B44,Letters!$C$4:$D$27,2,FALSE) & VLOOKUP($C44,Letters!$C$4:$D$27,2,FALSE) -> DB | E44: [U x R': [R' D2 R, U]] | F44: U x R2 D2 R U R' D2 R U' Lw U' | G44: =(len($F44)-len(SUBSTITUTE($F44,"R","")))+(len($F44)-len(SUBSTITUTE($F44,"L","")))+(len($F44)-len(SUBSTITUTE($F44,"U","")))+(len($F44)-len(SUBSTITUTE($F44,"D","")))+(len($F44)-len(SUBSTITUTE($F44,"F","")))+(len($F44)-len(SUBSTITUTE($F44,"B",""))) -> 11 | H44: =(len($F44)-len(SUBSTITUTE($F44,"R","")))+(len($F44)-len(SUBSTITUTE($F44,"L","")))+(len($F44)-len(SUBSTITUTE($F44,"U","")))+(len($F44)-len(SUBSTITUTE($F44,"D","")))+(len($F44)-len(SUBSTITUTE($F44,"F","")))+(len($F44)-len(SUBSTITUTE($F44,"B","")))+(len($F44)-len(SUBSTITUTE($F44,"2",""))) -> 14
A45: 1 | B45: UFL | C45: UFR | D45: =VLOOKUP($B45,Letters!$C$4:$D$27,2,FALSE) & VLOOKUP($C45,Letters!$C$4:$D$27,2,FALSE) -> DC | E45: [R' D' U': [U', R' D R]] | F45: R' D' U2 R' D R U R' D' R U D R | G45: =(len($F45)-len(SUBSTITUTE($F45,"R","")))+(len($F45)-len(SUBSTITUTE($F45,"L","")))+(len($F45)-len(SUBSTITUTE($F45,"U","")))+(len($F45)-len(SUBSTITUTE($F45,"D","")))+(len($F45)-len(SUBSTITUTE($F45,"F","")))+(len($F45)-len(SUBSTITUTE($F45,"B",""))) -> 13 | H45: =(len($F45)-len(SUBSTITUTE($F45,"R","")))+(len($F45)-len(SUBSTITUTE($F45,"L","")))+(len($F45)-len(SUBSTITUTE($F45,"U","")))+(len($F45)-len(SUBSTITUTE($F45,"D","")))+(len($F45)-len(SUBSTITUTE($F45,"F","")))+(len($F45)-len(SUBSTITUTE($F45,"B","")))+(len($F45)-len(SUBSTITUTE($F45,"2",""))) -> 14
A46: 1 | B46: UFL | C46: LFD | D46: =VLOOKUP($B46,Letters!$C$4:$D$27,2,FALSE) & VLOOKUP($C46,Letters!$C$4:$D$27,2,FALSE) -> DG | E46: [U2: [R' D R, U]] | F46: U2 R' D R U R' D' R U | G46: =(len($F46)-len(SUBSTITUTE($F46,"R","")))+(len($F46)-len(SUBSTITUTE($F46,"L","")))+(len($F46)-len(SUBSTITUTE($F46,"U","")))+(len($F46)-len(SUBSTITUTE($F46,"D","")))+(len($F46)-len(SUBSTITUTE($F46,"F","")))+(len($F46)-len(SUBSTITUTE($F46,"B",""))) -> 9 | H46: =(len($F46)-len(SUBSTITUTE($F46,"R","")))+(len($F46)-len(SUBSTITUTE($F46,"L","")))+(len($F46)-len(SUBSTITUTE($F46,"U","")))+(len($F46)-len(SUBSTITUTE($F46,"D","")))+(len($F46)-len(SUBSTITUTE($F46,"F","")))+(len($F46)-len(SUBSTITUTE($F46,"B","")))+(len($F46)-len(SUBSTITUTE($F46,"2",""))) -> 10
A47: 1 | B47: UFL | C47: LBD | D47: =VLOOKUP($B47,Letters!$C$4:$D$27,2,FALSE) & VLOOKUP($C47,Letters!$C$4:$D$27,2,FALSE) -> DH | E47: [U: [R D' R', U]] | F47: U R D' R' U R D R' U2 | G47: =(len($F47)-len(SUBSTITUTE($F47,"R","")))+(len($F47)-len(SUBSTITUTE($F47,"L","")))+(len($F47)-len(SUBSTITUTE($F47,"U","")))+(len($F47)-len(SUBSTITUTE($F47,"D","")))+(len($F47)-len(SUBSTITUTE($F47,"F","")))+(len($F47)-len(SUBSTITUTE($F47,"B",""))) -> 9 | H47: =(len($F47)-len(SUBSTITUTE($F47,"R","")))+(len($F47)-len(SUBSTITUTE($F47,"L","")))+(len($F47)-len(SUBSTITUTE($F47,"U","")))+(len($F47)-len(SUBSTITUTE($F47,"D","")))+(len($F47)-len(SUBSTITUTE($F47,"F","")))+(len($F47)-len(SUBSTITUTE($F47,"B","")))+(len($F47)-len(SUBSTITUTE($F47,"2",""))) -> 10
B48: UFL | C48: FRU | D48: =VLOOKUP($B48,Letters!$C$4:$D$27,2,FALSE) & VLOOKUP($C48,Letters!$C$4:$D$27,2,FALSE) -> DR | E48: [Lw' U': [U2, R D' R']] | F48: Lw' U R D' R' U2 R D R' U Lw | G48: =(len($F48)-len(SUBSTITUTE($F48,"R","")))+(len($F48)-len(SUBSTITUTE($F48,"L","")))+(len($F48)-len(SUBSTITUTE($F48,"U","")))+(len($F48)-len(SUBSTITUTE($F48,"D","")))+(len($F48)-len(SUBSTITUTE($F48,"F","")))+(len($F48)-len(SUBSTITUTE($F48,"B",""))) -> 11 | H48: =(len($F48)-len(SUBSTITUTE($F48,"R","")))+(len($F48)-len(SUBSTITUTE($F48,"L","")))+(len($F48)-len(SUBSTITUTE($F48,"U","")))+(len($F48)-len(SUBSTITUTE($F48,"D","")))+(len($F48)-len(SUBSTITUTE($F48,"F","")))+(len($F48)-len(SUBSTITUTE($F48,"B","")))+(len($F48)-len(SUBSTITUTE($F48,"2",""))) -> 12
...

Sheet E
B2: 3-Cycles
D3: =SUM(A6:A466)&"/"&COUNTA(D6:D466) -> 2/440
B4: Target 1 | C4: Target 2 | D4: Letter Pair | E4: Commutator | F4: Algorithm | G4: STM | H4: QTM
B6: UF | C6: UL | D6: =VLOOKUP($B6,Letters!$C$29:$D$52,2,FALSE) & VLOOKUP($C6,Letters!$C$29:$D$52,2,FALSE) -> AB | E6: [M U2 M, U'] | F6: M U2 M U' M' U2 M' U | G6: =(len($F6)-len(SUBSTITUTE($F6,"R","")))+(len($F6)-len(SUBSTITUTE($F6,"L","")))+(len($F6)-len(SUBSTITUTE($F6,"U","")))+(len($F6)-len(SUBSTITUTE($F6,"D","")))+(len($F6)-len(SUBSTITUTE($F6,"F","")))+(len($F6)-len(SUBSTITUTE($F6,"B","")))+(len($F6)-len(SUBSTITUTE($F6,"M","")))+(len($F6)-len(SUBSTITUTE($F6,"S","")))+(len($F6)-len(SUBSTITUTE($F6,"E",""))) -> 8 | H6: =(len($F6)-len(SUBSTITUTE($F6,"R","")))+(len($F6)-len(SUBSTITUTE($F6,"L","")))+(len($F6)-len(SUBSTITUTE($F6,"U","")))+(len($F6)-len(SUBSTITUTE($F6,"D","")))+(len($F6)-len(SUBSTITUTE($F6,"F","")))+(len($F6)-len(SUBSTITUTE($F6,"B","")))+(len($F6)-len(SUBSTITUTE($F6,"M","")))+(len($F6)-len(SUBSTITUTE($F6,"S","")))+(len($F6)-len(SUBSTITUTE($F6,"E","")))+(len($F6)-len(SUBSTITUTE($F6,"2",""))) -> 10
A7: 1 | B7: UF | C7: UB | D7: =VLOOKUP($B7,Letters!$C$29:$D$52,2,FALSE) & VLOOKUP($C7,Letters!$C$29:$D$52,2,FALSE) -> AC | E7: [U2, M'] | F7: U2 M' U2 M | G7: =(len($F7)-len(SUBSTITUTE($F7,"R","")))+(len($F7)-len(SUBSTITUTE($F7,"L","")))+(len($F7)-len(SUBSTITUTE($F7,"U","")))+(len($F7)-len(SUBSTITUTE($F7,"D","")))+(len($F7)-len(SUBSTITUTE($F7,"F","")))+(len($F7)-len(SUBSTITUTE($F7,"B","")))+(len($F7)-len(SUBSTITUTE($F7,"M","")))+(len($F7)-len(SUBSTITUTE($F7,"S","")))+(len($F7)-len(SUBSTITUTE($F7,"E",""))) -> 4 | H7: =(len($F7)-len(SUBSTITUTE($F7,"R","")))+(len($F7)-len(SUBSTITUTE($F7,"L","")))+(len($F7)-len(SUBSTITUTE($F7,"U","")))+(len($F7)-len(SUBSTITUTE($F7,"D","")))+(len($F7)-len(SUBSTITUTE($F7,"F","")))+(len($F7)-len(SUBSTITUTE($F7,"B","")))+(len($F7)-len(SUBSTITUTE($F7,"M","")))+(len($F7)-len(SUBSTITUTE($F7,"S","")))+(len($F7)-len(SUBSTITUTE($F7,"E","")))+(len($F7)-len(SUBSTITUTE($F7,"2",""))) -> 6
B8: UF | C8: UR | D8: =VLOOKUP($B8,Letters!$C$29:$D$52,2,FALSE) & VLOOKUP($C8,Letters!$C$29:$D$52,2,FALSE) -> AD | E8: [M U2 M, U] | F8: M U2 M U M' U2 M' U' | G8: =(len($F8)-len(SUBSTITUTE($F8,"R","")))+(len($F8)-len(SUBSTITUTE($F8,"L","")))+(len($F8)-len(SUBSTITUTE($F8,"U","")))+(len($F8)-len(SUBSTITUTE($F8,"D","")))+(len($F8)-len(SUBSTITUTE($F8,"F","")))+(len($F8)-len(SUBSTITUTE($F8,"B","")))+(len($F8)-len(SUBSTITUTE($F8,"M","")))+(len($F8)-len(SUBSTITUTE($F8,"S","")))+(len($F8)-len(SUBSTITUTE($F8,"E",""))) -> 8 | H8: =(len($F8)-len(SUBSTITUTE($F8,"R","")))+(len($F8)-len(SUBSTITUTE($F8,"L","")))+(len($F8)-len(SUBSTITUTE($F8,"U","")))+(len($F8)-len(SUBSTITUTE($F8,"D","")))+(len($F8)-len(SUBSTITUTE($F8,"F","")))+(len($F8)-len(SUBSTITUTE($F8,"B","")))+(len($F8)-len(SUBSTITUTE($F8,"M","")))+(len($F8)-len(SUBSTITUTE($F8,"S","")))+(len($F8)-len(SUBSTITUTE($F8,"E","")))+(len($F8)-len(SUBSTITUTE($F8,"2",""))) -> 10
B9: UF | C9: LD | D9: =VLOOKUP($B9,Letters!$C$29:$D$52,2,FALSE) & VLOOKUP($C9,Letters!$C$29:$D$52,2,FALSE) -> AE | E9: [U: [S', Rw' D Rw]] | F9: U S' Rw' D Rw S Rw' D' Rw U' | G9: =(len($F9)-len(SUBSTITUTE($F9,"R","")))+(len($F9)-len(SUBSTITUTE($F9,"L","")))+(len($F9)-len(SUBSTITUTE($F9,"U","")))+(len($F9)-len(SUBSTITUTE($F9,"D","")))+(len($F9)-len(SUBSTITUTE($F9,"F","")))+(len($F9)-len(SUBSTITUTE($F9,"B","")))+(len($F9)-len(SUBSTITUTE($F9,"M","")))+(len($F9)-len(SUBSTITUTE($F9,"S","")))+(len($F9)-len(SUBSTITUTE($F9,"E",""))) -> 10 | H9: =(len($F9)-len(SUBSTITUTE($F9,"R","")))+(len($F9)-len(SUBSTITUTE($F9,"L","")))+(len($F9)-len(SUBSTITUTE($F9,"U","")))+(len($F9)-len(SUBSTITUTE($F9,"D","")))+(len($F9)-len(SUBSTITUTE($F9,"F","")))+(len($F9)-len(SUBSTITUTE($F9,"B","")))+(len($F9)-len(SUBSTITUTE($F9,"M","")))+(len($F9)-len(SUBSTITUTE($F9,"S","")))+(len($F9)-len(SUBSTITUTE($F9,"E","")))+(len($F9)-len(SUBSTITUTE($F9,"2",""))) -> 10
B10: UF | C10: LB | D10: =VLOOKUP($B10,Letters!$C$29:$D$52,2,FALSE) & VLOOKUP($C10,Letters!$C$29:$D$52,2,FALSE) -> AF | E10: [F': [L2, E'] | F10: F' Rw2 E Rw2 E F | G10: =(len($F10)-len(SUBSTITUTE($F10,"R","")))+(len($F10)-len(SUBSTITUTE($F10,"L","")))+(len($F10)-len(SUBSTITUTE($F10,"U","")))+(len($F10)-len(SUBSTITUTE($F10,"D","")))+(len($F10)-len(SUBSTITUTE($F10,"F","")))+(len($F10)-len(SUBSTITUTE($F10,"B","")))+(len($F10)-len(SUBSTITUTE($F10,"M","")))+(len($F10)-len(SUBSTITUTE($F10,"S","")))+(len($F10)-len(SUBSTITUTE($F10,"E",""))) -> 6 | H10: =(len($F10)-len(SUBSTITUTE($F10,"R","")))+(len($F10)-len(SUBSTITUTE($F10,"L","")))+(len($F10)-len(SUBSTITUTE($F10,"U","")))+(len($F10)-len(SUBSTITUTE($F10,"D","")))+(len($F10)-len(SUBSTITUTE($F10,"F","")))+(len($F10)-len(SUBSTITUTE($F10,"B","")))+(len($F10)-len(SUBSTITUTE($F10,"M","")))+(len($F10)-len(SUBSTITUTE($F10,"S","")))+(len($F10)-len(SUBSTITUTE($F10,"E","")))+(len($F10)-len(SUBSTITUTE($F10,"2",""))) -> 8
B11: UF | C11: LU | D11: =VLOOKUP($B11,Letters!$C$29:$D$52,2,FALSE) & VLOOKUP($C11,Letters!$C$29:$D$52,2,FALSE) -> AG | E11: [L' F': [L2, E']] | G11: =(len($F11)-len(SUBSTITUTE($F11,"R","")))+(len($F11)-len(SUBSTITUTE($F11,"L","")))+(len($F11)-len(SUBSTITUTE($F11,"U","")))+(len($F11)-len(SUBSTITUTE($F11,"D","")))+(len($F11)-len(SUBSTITUTE($F11,"F","")))+(len($F11)-len(SUBSTITUTE($F11,"B","")))+(len($F11)-len(SUBSTITUTE($F11,"M","")))+(len($F11)-len(SUBSTITUTE($F11,"S","")))+(len($F11)-len(SUBSTITUTE($F11,"E",""))) -> 0 | H11: =(len($F11)-len(SUBSTITUTE($F11,"R","")))+(len($F11)-len(SUBSTITUTE($F11,"L","")))+(len($F11)-len(SUBSTITUTE($F11,"U","")))+(len($F11)-len(SUBSTITUTE($F11,"D","")))+(len($F11)-len(SUBSTITUTE($F11,"F","")))+(len($F11)-len(SUBSTITUTE($F11,"B","")))+(len($F11)-len(SUBSTITUTE($F11,"M","")))+(len($F11)-len(SUBSTITUTE($F11,"S","")))+(len($F11)-len(SUBSTITUTE($F11,"E","")))+(len($F11)-len(SUBSTITUTE($F11,"2",""))) -> 0
B12: UF | C12: LF | D12: =VLOOKUP($B12,Letters!$C$29:$D$52,2,FALSE) & VLOOKUP($C12,Letters!$C$29:$D$52,2,FALSE) -> AH | E12: [L2 F: [E', L2]] | G12: =(len($F12)-len(SUBSTITUTE($F12,"R","")))+(len($F12)-len(SUBSTITUTE($F12,"L","")))+(len($F12)-len(SUBSTITUTE($F12,"U","")))+(len($F12)-len(SUBSTITUTE($F12,"D","")))+(len($F12)-len(SUBSTITUTE($F12,"F","")))+(len($F12)-len(SUBSTITUTE($F12,"B","")))+(len($F12)-len(SUBSTITUTE($F12,"M","")))+(len($F12)-len(SUBSTITUTE($F12,"S","")))+(len($F12)-len(SUBSTITUTE($F12,"E",""))) -> 0 | H12: =(len($F12)-len(SUBSTITUTE($F12,"R","")))+(len($F12)-len(SUBSTITUTE($F12,"L","")))+(len($F12)-len(SUBSTITUTE($F12,"U","")))+(len($F12)-len(SUBSTITUTE($F12,"D","")))+(len($F12)-len(SUBSTITUTE($F12,"F","")))+(len($F12)-len(SUBSTITUTE($F12,"B","")))+(len($F12)-len(SUBSTITUTE($F12,"M","")))+(len($F12)-len(SUBSTITUTE($F12,"S","")))+(len($F12)-len(SUBSTITUTE($F12,"E","")))+(len($F12)-len(SUBSTITUTE($F12,"2",""))) -> 0
B13: UF | C13: FL | D13: =VLOOKUP($B13,Letters!$C$29:$D$52,2,FALSE) & VLOOKUP($C13,Letters!$C$29:$D$52,2,FALSE) -> AJ | E13: [U' L' U': [M', U2]] | F13: U' L' U' M' U2 M U' L U | G13: =(len($F13)-len(SUBSTITUTE($F13,"R","")))+(len($F13)-len(SUBSTITUTE($F13,"L","")))+(len($F13)-len(SUBSTITUTE($F13,"U","")))+(len($F13)-len(SUBSTITUTE($F13,"D","")))+(len($F13)-len(SUBSTITUTE($F13,"F","")))+(len($F13)-len(SUBSTITUTE($F13,"B","")))+(len($F13)-len(SUBSTITUTE($F13,"M","")))+(len($F13)-len(SUBSTITUTE($F13,"S","")))+(len($F13)-len(SUBSTITUTE($F13,"E",""))) -> 9 | H13: =(len($F13)-len(SUBSTITUTE($F13,"R","")))+(len($F13)-len(SUBSTITUTE($F13,"L","")))+(len($F13)-len(SUBSTITUTE($F13,"U","")))+(len($F13)-len(SUBSTITUTE($F13,"D","")))+(len($F13)-len(SUBSTITUTE($F13,"F","")))+(len($F13)-len(SUBSTITUTE($F13,"B","")))+(len($F13)-len(SUBSTITUTE($F13,"M","")))+(len($F13)-len(SUBSTITUTE($F13,"S","")))+(len($F13)-len(SUBSTITUTE($F13,"E","")))+(len($F13)-len(SUBSTITUTE($F13,"2",""))) -> 10
B14: UF | C14: FR | D14: =VLOOKUP($B14,Letters!$C$29:$D$52,2,FALSE) & VLOOKUP($C14,Letters!$C$29:$D$52,2,FALSE) -> AL | E14: - | F14: R' f2 R2 U' R2' f2 R2 U' R' | G14: =(len($F14)-len(SUBSTITUTE($F14,"R","")))+(len($F14)-len(SUBSTITUTE($F14,"L","")))+(len($F14)-len(SUBSTITUTE($F14,"U","")))+(len($F14)-len(SUBSTITUTE($F14,"D","")))+(len($F14)-len(SUBSTITUTE($F14,"F","")))+(len($F14)-len(SUBSTITUTE($F14,"B","")))+(len($F14)-len(SUBSTITUTE($F14,"f","")))+(len($F14)-len(SUBSTITUTE($F14,"S","")))+(len($F14)-len(SUBSTITUTE($F14,"E",""))) -> 9 | H14: =(len($F14)-len(SUBSTITUTE($F14,"R","")))+(len($F14)-len(SUBSTITUTE($F14,"L","")))+(len($F14)-len(SUBSTITUTE($F14,"U","")))+(len($F14)-len(SUBSTITUTE($F14,"D","")))+(len($F14)-len(SUBSTITUTE($F14,"F","")))+(len($F14)-len(SUBSTITUTE($F14,"B","")))+(len($F14)-len(SUBSTITUTE($F14,"M","")))+(len($F14)-len(SUBSTITUTE($F14,"S","")))+(len($F14)-len(SUBSTITUTE($F14,"E","")))+(len($F14)-len(SUBSTITUTE($F14,"2",""))) -> 12
B15: UF | C15: RD | D15: =VLOOKUP($B15,Letters!$C$29:$D$52,2,FALSE) & VLOOKUP($C15,Letters!$C$29:$D$52,2,FALSE) -> AM | E15: [R' F: [R2, E]] | G15: =(len($F15)-len(SUBSTITUTE($F15,"R","")))+(len($F15)-len(SUBSTITUTE($F15,"L","")))+(len($F15)-len(SUBSTITUTE($F15,"U","")))+(len($F15)-len(SUBSTITUTE($F15,"D","")))+(len($F15)-len(SUBSTITUTE($F15,"F","")))+(len($F15)-len(SUBSTITUTE($F15,"B","")))+(len($F15)-len(SUBSTITUTE($F15,"M","")))+(len($F15)-len(SUBSTITUTE($F15,"S","")))+(len($F15)-len(SUBSTITUTE($F15,"E",""))) -> 0 | H15: =(len($F15)-len(SUBSTITUTE($F15,"R","")))+(len($F15)-len(SUBSTITUTE($F15,"L","")))+(len($F15)-len(SUBSTITUTE($F15,"U","")))+(len($F15)-len(SUBSTITUTE($F15,"D","")))+(len($F15)-len(SUBSTITUTE($F15,"F","")))+(len($F15)-len(SUBSTITUTE($F15,"B","")))+(len($F15)-len(SUBSTITUTE($F15,"M","")))+(len($F15)-len(SUBSTITUTE($F15,"S","")))+(len($F15)-len(SUBSTITUTE($F15,"E","")))+(len($F15)-len(SUBSTITUTE($F15,"2",""))) -> 0
B16: UF | C16: RF | D16: =VLOOKUP($B16,Letters!$C$29:$D$52,2,FALSE) & VLOOKUP($C16,Letters!$C$29:$D$52,2,FALSE) -> AN | E16: [R2 F: [R2, E]] | G16: =(len($F16)-len(SUBSTITUTE($F16,"R","")))+(len($F16)-len(SUBSTITUTE($F16,"L","")))+(len($F16)-len(SUBSTITUTE($F16,"U","")))+(len($F16)-len(SUBSTITUTE($F16,"D","")))+(len($F16)-len(SUBSTITUTE($F16,"F","")))+(len($F16)-len(SUBSTITUTE($F16,"B","")))+(len($F16)-len(SUBSTITUTE($F16,"M","")))+(len($F16)-len(SUBSTITUTE($F16,"S","")))+(len($F16)-len(SUBSTITUTE($F16,"E",""))) -> 0 | H16: =(len($F16)-len(SUBSTITUTE($F16,"R","")))+(len($F16)-len(SUBSTITUTE($F16,"L","")))+(len($F16)-len(SUBSTITUTE($F16,"U","")))+(len($F16)-len(SUBSTITUTE($F16,"D","")))+(len($F16)-len(SUBSTITUTE($F16,"F","")))+(len($F16)-len(SUBSTITUTE($F16,"B","")))+(len($F16)-len(SUBSTITUTE($F16,"M","")))+(len($F16)-len(SUBSTITUTE($F16,"S","")))+(len($F16)-len(SUBSTITUTE($F16,"E","")))+(len($F16)-len(SUBSTITUTE($F16,"2",""))) -> 0
B17: UF | C17: RU | D17: =VLOOKUP($B17,Letters!$C$29:$D$52,2,FALSE) & VLOOKUP($C17,Letters!$C$29:$D$52,2,FALSE) -> AO | E17: [D: [R' F R , S']] | F17: D R' F R S' R' F' R S D' | G17: =(len($F17)-len(SUBSTITUTE($F17,"R","")))+(len($F17)-len(SUBSTITUTE($F17,"L","")))+(len($F17)-len(SUBSTITUTE($F17,"U","")))+(len($F17)-len(SUBSTITUTE($F17,"D","")))+(len($F17)-len(SUBSTITUTE($F17,"F","")))+(len($F17)-len(SUBSTITUTE($F17,"B","")))+(len($F17)-len(SUBSTITUTE($F17,"M","")))+(len($F17)-len(SUBSTITUTE($F17,"S","")))+(len($F17)-len(SUBSTITUTE($F17,"E",""))) -> 10 | H17: =(len($F17)-len(SUBSTITUTE($F17,"R","")))+(len($F17)-len(SUBSTITUTE($F17,"L","")))+(len($F17)-len(SUBSTITUTE($F17,"U","")))+(len($F17)-len(SUBSTITUTE($F17,"D","")))+(len($F17)-len(SUBSTITUTE($F17,"F","")))+(len($F17)-len(SUBSTITUTE($F17,"B","")))+(len($F17)-len(SUBSTITUTE($F17,"M","")))+(len($F17)-len(SUBSTITUTE($F17,"S","")))+(len($F17)-len(SUBSTITUTE($F17,"E","")))+(len($F17)-len(SUBSTITUTE($F17,"2",""))) -> 10
B18: UF | C18: RB | D18: =VLOOKUP($B18,Letters!$C$29:$D$52,2,FALSE) & VLOOKUP($C18,Letters!$C$29:$D$52,2,FALSE) -> AP | E18: [F: [R2, E]] | G18: =(len($F18)-len(SUBSTITUTE($F18,"R","")))+(len($F18)-len(SUBSTITUTE($F18,"L","")))+(len($F18)-len(SUBSTITUTE($F18,"U","")))+(len($F18)-len(SUBSTITUTE($F18,"D","")))+(len($F18)-len(SUBSTITUTE($F18,"F","")))+(len($F18)-len(SUBSTITUTE($F18,"B","")))+(len($F18)-len(SUBSTITUTE($F18,"M","")))+(len($F18)-len(SUBSTITUTE($F18,"S","")))+(len($F18)-len(SUBSTITUTE($F18,"E",""))) -> 0 | H18: =(len($F18)-len(SUBSTITUTE($F18,"R","")))+(len($F18)-len(SUBSTITUTE($F18,"L","")))+(len($F18)-len(SUBSTITUTE($F18,"U","")))+(len($F18)-len(SUBSTITUTE($F18,"D","")))+(len($F18)-len(SUBSTITUTE($F18,"F","")))+(len($F18)-len(SUBSTITUTE($F18,"B","")))+(len($F18)-len(SUBSTITUTE($F18,"M","")))+(len($F18)-len(SUBSTITUTE($F18,"S","")))+(len($F18)-len(SUBSTITUTE($F18,"E","")))+(len($F18)-len(SUBSTITUTE($F18,"2",""))) -> 0
B19: UF | C19: BD | D19: =VLOOKUP($B19,Letters!$C$29:$D$52,2,FALSE) & VLOOKUP($C19,Letters!$C$29:$D$52,2,FALSE) -> AW | E19: [D': [R F R', S']] | F19: D' Lw D Lw' S' Lw D' Lw' S D | G19: =(len($F19)-len(SUBSTITUTE($F19,"R","")))+(len($F19)-len(SUBSTITUTE($F19,"L","")))+(len($F19)-len(SUBSTITUTE($F19,"U","")))+(len($F19)-len(SUBSTITUTE($F19,"D","")))+(len($F19)-len(SUBSTITUTE($F19,"F","")))+(len($F19)-len(SUBSTITUTE($F19,"B","")))+(len($F19)-len(SUBSTITUTE($F19,"M","")))+(len($F19)-len(SUBSTITUTE($F19,"S","")))+(len($F19)-len(SUBSTITUTE($F19,"E",""))) -> 10 | H19: =(len($F19)-len(SUBSTITUTE($F19,"R","")))+(len($F19)-len(SUBSTITUTE($F19,"L","")))+(len($F19)-len(SUBSTITUTE($F19,"U","")))+(len($F19)-len(SUBSTITUTE($F19,"D","")))+(len($F19)-len(SUBSTITUTE($F19,"F","")))+(len($F19)-len(SUBSTITUTE($F19,"B","")))+(len($F19)-len(SUBSTITUTE($F19,"M","")))+(len($F19)-len(SUBSTITUTE($F19,"S","")))+(len($F19)-len(SUBSTITUTE($F19,"E","")))+(len($F19)-len(SUBSTITUTE($F19,"2",""))) -> 10
B20: UF | C20: BR | D20: =VLOOKUP($B20,Letters!$C$29:$D$52,2,FALSE) & VLOOKUP($C20,Letters!$C$29:$D$52,2,FALSE) -> AR | E20: [U R' U: [M', U2]] | F20: U R' U M' U2 M U R U' | G20: =(len($F20)-len(SUBSTITUTE($F20,"R","")))+(len($F20)-len(SUBSTITUTE($F20,"L","")))+(len($F20)-len(SUBSTITUTE($F20,"U","")))+(len($F20)-len(SUBSTITUTE($F20,"D","")))+(len($F20)-len(SUBSTITUTE($F20,"F","")))+(len($F20)-len(SUBSTITUTE($F20,"B","")))+(len($F20)-len(SUBSTITUTE($F20,"M","")))+(len($F20)-len(SUBSTITUTE($F20,"S","")))+(len($F20)-len(SUBSTITUTE($F20,"E",""))) -> 9 | H20: =(len($F20)-len(SUBSTITUTE($F20,"R","")))+(len($F20)-len(SUBSTITUTE($F20,"L","")))+(len($F20)-len(SUBSTITUTE($F20,"U","")))+(len($F20)-len(SUBSTITUTE($F20,"D","")))+(len($F20)-len(SUBSTITUTE($F20,"F","")))+(len($F20)-len(SUBSTITUTE($F20,"B","")))+(len($F20)-len(SUBSTITUTE($F20,"M","")))+(len($F20)-len(SUBSTITUTE($F20,"S","")))+(len($F20)-len(SUBSTITUTE($F20,"E","")))+(len($F20)-len(SUBSTITUTE($F20,"2",""))) -> 10
B21: UF | C21: BU | D21: =VLOOKUP($B21,Letters!$C$29:$D$52,2,FALSE) & VLOOKUP($C21,Letters!$C$29:$D$52,2,FALSE) -> AS | E21: [U: [S, R' F' R]] | F21: U S R' F' R S' R' F R U' | G21: =(len($F21)-len(SUBSTITUTE($F21,"R","")))+(len($F21)-len(SUBSTITUTE($F21,"L","")))+(len($F21)-len(SUBSTITUTE($F21,"U","")))+(len($F21)-len(SUBSTITUTE($F21,"D","")))+(len($F21)-len(SUBSTITUTE($F21,"F","")))+(len($F21)-len(SUBSTITUTE($F21,"B","")))+(len($F21)-len(SUBSTITUTE($F21,"M","")))+(len($F21)-len(SUBSTITUTE($F21,"S","")))+(len($F21)-len(SUBSTITUTE($F21,"E",""))) -> 10 | H21: =(len($F21)-len(SUBSTITUTE($F21,"R","")))+(len($F21)-len(SUBSTITUTE($F21,"L","")))+(len($F21)-len(SUBSTITUTE($F21,"U","")))+(len($F21)-len(SUBSTITUTE($F21,"D","")))+(len($F21)-len(SUBSTITUTE($F21,"F","")))+(len($F21)-len(SUBSTITUTE($F21,"B","")))+(len($F21)-len(SUBSTITUTE($F21,"M","")))+(len($F21)-len(SUBSTITUTE($F21,"S","")))+(len($F21)-len(SUBSTITUTE($F21,"E","")))+(len($F21)-len(SUBSTITUTE($F21,"2",""))) -> 10
B22: UF | C22: BL | D22: =VLOOKUP($B22,Letters!$C$29:$D$52,2,FALSE) & VLOOKUP($C22,Letters!$C$29:$D$52,2,FALSE) -> AT | E22: [U' L U': [M', U2]] | F22: U' L U' M' U2 M U' L' U | G22: =(len($F22)-len(SUBSTITUTE($F22,"R","")))+(len($F22)-len(SUBSTITUTE($F22,"L","")))+(len($F22)-len(SUBSTITUTE($F22,"U","")))+(len($F22)-len(SUBSTITUTE($F22,"D","")))+(len($F22)-len(SUBSTITUTE($F22,"F","")))+(len($F22)-len(SUBSTITUTE($F22,"B","")))+(len($F22)-len(SUBSTITUTE($F22,"M","")))+(len($F22)-len(SUBSTITUTE($F22,"S","")))+(len($F22)-len(SUBSTITUTE($F22,"E",""))) -> 9 | H22: =(len($F22)-len(SUBSTITUTE($F22,"R","")))+(len($F22)-len(SUBSTITUTE($F22,"L","")))+(len($F22)-len(SUBSTITUTE($F22,"U","")))+(len($F22)-len(SUBSTITUTE($F22,"D","")))+(len($F22)-len(SUBSTITUTE($F22,"F","")))+(len($F22)-len(SUBSTITUTE($F22,"B","")))+(len($F22)-len(SUBSTITUTE($F22,"M","")))+(len($F22)-len(SUBSTITUTE($F22,"S","")))+(len($F22)-len(SUBSTITUTE($F22,"E","")))+(len($F22)-len(SUBSTITUTE($F22,"2",""))) -> 10
B23: UF | C23: DB | D23: =VLOOKUP($B23,Letters!$C$29:$D$52,2,FALSE) & VLOOKUP($C23,Letters!$C$29:$D$52,2,FALSE) -> AU | E23: [M2: [M, U2]] | F23: M' U2 M' U2 M2 | G23: =(len($F23)-len(SUBSTITUTE($F23,"R","")))+(len($F23)-len(SUBSTITUTE($F23,"L","")))+(len($F23)-len(SUBSTITUTE($F23,"U","")))+(len($F23)-len(SUBSTITUTE($F23,"D","")))+(len($F23)-len(SUBSTITUTE($F23,"F","")))+(len($F23)-len(SUBSTITUTE($F23,"B","")))+(len($F23)-len(SUBSTITUTE($F23,"M","")))+(len($F23)-len(SUBSTITUTE($F23,"S","")))+(len($F23)-len(SUBSTITUTE($F23,"E",""))) -> 5 | H23: =(len($F23)-len(SUBSTITUTE($F23,"R","")))+(len($F23)-len(SUBSTITUTE($F23,"L","")))+(len($F23)-len(SUBSTITUTE($F23,"U","")))+(len($F23)-len(SUBSTITUTE($F23,"D","")))+(len($F23)-len(SUBSTITUTE($F23,"F","")))+(len($F23)-len(SUBSTITUTE($F23,"B","")))+(len($F23)-len(SUBSTITUTE($F23,"M","")))+(len($F23)-len(SUBSTITUTE($F23,"S","")))+(len($F23)-len(SUBSTITUTE($F23,"E","")))+(len($F23)-len(SUBSTITUTE($F23,"2",""))) -> 8
B24: UF | C24: DL | D24: =VLOOKUP($B24,Letters!$C$29:$D$52,2,FALSE) & VLOOKUP($C24,Letters!$C$29:$D$52,2,FALSE) -> AV | E24: [R' F: [F2 , R' S' R]] | F24: R' F' R' S' R F2 R' S R F' R | G24: =(len($F24)-len(SUBSTITUTE($F24,"R","")))+(len($F24)-len(SUBSTITUTE($F24,"L","")))+(len($F24)-len(SUBSTITUTE($F24,"U","")))+(len($F24)-len(SUBSTITUTE($F24,"D","")))+(len($F24)-len(SUBSTITUTE($F24,"F","")))+(len($F24)-len(SUBSTITUTE($F24,"B","")))+(len($F24)-len(SUBSTITUTE($F24,"M","")))+(len($F24)-len(SUBSTITUTE($F24,"S","")))+(len($F24)-len(SUBSTITUTE($F24,"E",""))) -> 11 | H24: =(len($F24)-len(SUBSTITUTE($F24,"R","")))+(len($F24)-len(SUBSTITUTE($F24,"L","")))+(len($F24)-len(SUBSTITUTE($F24,"U","")))+(len($F24)-len(SUBSTITUTE($F24,"D","")))+(len($F24)-len(SUBSTITUTE($F24,"F","")))+(len($F24)-len(SUBSTITUTE($F24,"B","")))+(len($F24)-len(SUBSTITUTE($F24,"M","")))+(len($F24)-len(SUBSTITUTE($F24,"S","")))+(len($F24)-len(SUBSTITUTE($F24,"E","")))+(len($F24)-len(SUBSTITUTE($F24,"2",""))) -> 12
B25: UF | C25: DR | D25: =VLOOKUP($B25,Letters!$C$29:$D$52,2,FALSE) & VLOOKUP($C25,Letters!$C$29:$D$52,2,FALSE) -> AI | E25: [U R2 U: [M', U2]] | F25: U R2 U M' U2 M U R2 U' | G25: =(len($F25)-len(SUBSTITUTE($F25,"R","")))+(len($F25)-len(SUBSTITUTE($F25,"L","")))+(len($F25)-len(SUBSTITUTE($F25,"U","")))+(len($F25)-len(SUBSTITUTE($F25,"D","")))+(len($F25)-len(SUBSTITUTE($F25,"F","")))+(len($F25)-len(SUBSTITUTE($F25,"B","")))+(len($F25)-len(SUBSTITUTE($F25,"M","")))+(len($F25)-len(SUBSTITUTE($F25,"S","")))+(len($F25)-len(SUBSTITUTE($F25,"E",""))) -> 9 | H25: =(len($F25)-len(SUBSTITUTE($F25,"R","")))+(len($F25)-len(SUBSTITUTE($F25,"L","")))+(len($F25)-len(SUBSTITUTE($F25,"U","")))+(len($F25)-len(SUBSTITUTE($F25,"D","")))+(len($F25)-len(SUBSTITUTE($F25,"F","")))+(len($F25)-len(SUBSTITUTE($F25,"B","")))+(len($F25)-len(SUBSTITUTE($F25,"M","")))+(len($F25)-len(SUBSTITUTE($F25,"S","")))+(len($F25)-len(SUBSTITUTE($F25,"E","")))+(len($F25)-len(SUBSTITUTE($F25,"2",""))) -> 12 | I25: =AVERAGE(H6:H25) -> 7.4
B27: UL | C27: UF | D27: =VLOOKUP($B27,Letters!$C$29:$D$52,2,FALSE) & VLOOKUP($C27,Letters!$C$29:$D$52,2,FALSE) -> BA | E27: [R' F: [R S R', F2]] | F27: R' F R S R' F2 R S' R' F R | G27: =(len($F27)-len(SUBSTITUTE($F27,"R","")))+(len($F27)-len(SUBSTITUTE($F27,"L","")))+(len($F27)-len(SUBSTITUTE($F27,"U","")))+(len($F27)-len(SUBSTITUTE($F27,"D","")))+(len($F27)-len(SUBSTITUTE($F27,"F","")))+(len($F27)-len(SUBSTITUTE($F27,"B","")))+(len($F27)-len(SUBSTITUTE($F27,"M","")))+(len($F27)-len(SUBSTITUTE($F27,"S","")))+(len($F27)-len(SUBSTITUTE($F27,"E",""))) -> 11 | H27: =(len($F27)-len(SUBSTITUTE($F27,"R","")))+(len($F27)-len(SUBSTITUTE($F27,"L","")))+(len($F27)-len(SUBSTITUTE($F27,"U","")))+(len($F27)-len(SUBSTITUTE($F27,"D","")))+(len($F27)-len(SUBSTITUTE($F27,"F","")))+(len($F27)-len(SUBSTITUTE($F27,"B","")))+(len($F27)-len(SUBSTITUTE($F27,"M","")))+(len($F27)-len(SUBSTITUTE($F27,"S","")))+(len($F27)-len(SUBSTITUTE($F27,"E","")))+(len($F27)-len(SUBSTITUTE($F27,"2",""))) -> 12
B28: UL | C28: UB | D28: =VLOOKUP($B28,Letters!$C$29:$D$52,2,FALSE) & VLOOKUP($C28,Letters!$C$29:$D$52,2,FALSE) -> BC | E28: - | F28: D R U R' U' R' U' R' U R U D' | G28: =(len($F28)-len(SUBSTITUTE($F28,"R","")))+(len($F28)-len(SUBSTITUTE($F28,"L","")))+(len($F28)-len(SUBSTITUTE($F28,"U","")))+(len($F28)-len(SUBSTITUTE($F28,"D","")))+(len($F28)-len(SUBSTITUTE($F28,"F","")))+(len($F28)-len(SUBSTITUTE($F28,"B","")))+(len($F28)-len(SUBSTITUTE($F28,"M","")))+(len($F28)-len(SUBSTITUTE($F28,"S","")))+(len($F28)-len(SUBSTITUTE($F28,"E",""))) -> 12 | H28: =(len($F28)-len(SUBSTITUTE($F28,"R","")))+(len($F28)-len(SUBSTITUTE($F28,"L","")))+(len($F28)-len(SUBSTITUTE($F28,"U","")))+(len($F28)-len(SUBSTITUTE($F28,"D","")))+(len($F28)-len(SUBSTITUTE($F28,"F","")))+(len($F28)-len(SUBSTITUTE($F28,"B","")))+(len($F28)-len(SUBSTITUTE($F28,"M","")))+(len($F28)-len(SUBSTITUTE($F28,"S","")))+(len($F28)-len(SUBSTITUTE($F28,"E","")))+(len($F28)-len(SUBSTITUTE($F28,"2",""))) -> 12
B29: UL | C29: UR | D29: =VLOOKUP($B29,Letters!$C$29:$D$52,2,FALSE) & VLOOKUP($C29,Letters!$C$29:$D$52,2,FALSE) -> BD | E29: [U: [M', U2]] | F29: U M' U2 M U | G29: =(len($F29)-len(SUBSTITUTE($F29,"R","")))+(len($F29)-len(SUBSTITUTE($F29,"L","")))+(len($F29)-len(SUBSTITUTE($F29,"U","")))+(len($F29)-len(SUBSTITUTE($F29,"D","")))+(len($F29)-len(SUBSTITUTE($F29,"F","")))+(len($F29)-len(SUBSTITUTE($F29,"B","")))+(len($F29)-len(SUBSTITUTE($F29,"M","")))+(len($F29)-len(SUBSTITUTE($F29,"S","")))+(len($F29)-len(SUBSTITUTE($F29,"E",""))) -> 5 | H29: =(len($F29)-len(SUBSTITUTE($F29,"R","")))+(len($F29)-len(SUBSTITUTE($F29,"L","")))+(len($F29)-len(SUBSTITUTE($F29,"U","")))+(len($F29)-len(SUBSTITUTE($F29,"D","")))+(len($F29)-len(SUBSTITUTE($F29,"F","")))+(len($F29)-len(SUBSTITUTE($F29,"B","")))+(len($F29)-len(SUBSTITUTE($F29,"M","")))+(len($F29)-len(SUBSTITUTE($F29,"S","")))+(len($F29)-len(SUBSTITUTE($F29,"E","")))+(len($F29)-len(SUBSTITUTE($F29,"2",""))) -> 6
B30: UL | C30: LD | D30: =VLOOKUP($B30,Letters!$C$29:$D$52,2,FALSE) & VLOOKUP($C30,Letters!$C$29:$D$52,2,FALSE) -> BE | E30: [S', Rw' D Rw] | F30: S' Rw' D Rw S Rw' D' Rw | G30: =(len($F30)-len(SUBSTITUTE($F30,"R","")))+(len($F30)-len(SUBSTITUTE($F30,"L","")))+(len($F30)-len(SUBSTITUTE($F30,"U","")))+(len($F30)-len(SUBSTITUTE($F30,"D","")))+(len($F30)-len(SUBSTITUTE($F30,"F","")))+(len($F30)-len(SUBSTITUTE($F30,"B","")))+(len($F30)-len(SUBSTITUTE($F30,"M","")))+(len($F30)-len(SUBSTITUTE($F30,"S","")))+(len($F30)-len(SUBSTITUTE($F30,"E",""))) -> 8 | H30: =(len($F30)-len(SUBSTITUTE($F30,"R","")))+(len($F30)-len(SUBSTITUTE($F30,"L","")))+(len($F30)-len(SUBSTITUTE($F30,"U","")))+(len($F30)-len(SUBSTITUTE($F30,"D","")))+(len($F30)-len(SUBSTITUTE($F30,"F","")))+(len($F30)-len(SUBSTITUTE($F30,"B","")))+(len($F30)-len(SUBSTITUTE($F30,"M","")))+(len($F30)-len(SUBSTITUTE($F30,"S","")))+(len($F30)-len(SUBSTITUTE($F30,"E","")))+(len($F30)-len(SUBSTITUTE($F30,"2",""))) -> 8
B31: UL | C31: LB | D31: =VLOOKUP($B31,Letters!$C$29:$D$52,2,FALSE) & VLOOKUP($C31,Letters!$C$29:$D$52,2,FALSE) -> BF | E31: [Fw L': [S', L2]] | F31: Fw Rw' E' Rw2 E' Rw' Fw' | G31: =(len($F31)-len(SUBSTITUTE($F31,"R","")))+(len($F31)-len(SUBSTITUTE($F31,"L","")))+(len($F31)-len(SUBSTITUTE($F31,"U","")))+(len($F31)-len(SUBSTITUTE($F31,"D","")))+(len($F31)-len(SUBSTITUTE($F31,"F","")))+(len($F31)-len(SUBSTITUTE($F31,"B","")))+(len($F31)-len(SUBSTITUTE($F31,"M","")))+(len($F31)-len(SUBSTITUTE($F31,"S","")))+(len($F31)-len(SUBSTITUTE($F31,"E",""))) -> 7 | H31: =(len($F31)-len(SUBSTITUTE($F31,"R","")))+(len($F31)-len(SUBSTITUTE($F31,"L","")))+(len($F31)-len(SUBSTITUTE($F31,"U","")))+(len($F31)-len(SUBSTITUTE($F31,"D","")))+(len($F31)-len(SUBSTITUTE($F31,"F","")))+(len($F31)-len(SUBSTITUTE($F31,"B","")))+(len($F31)-len(SUBSTITUTE($F31,"M","")))+(len($F31)-len(SUBSTITUTE($F31,"S","")))+(len($F31)-len(SUBSTITUTE($F31,"E","")))+(len($F31)-len(SUBSTITUTE($F31,"2",""))) -> 8
B32: UL | C32: LF | D32: =VLOOKUP($B32,Letters!$C$29:$D$52,2,FALSE) & VLOOKUP($C32,Letters!$C$29:$D$52,2,FALSE) -> BH | E32: [R' F2: [R S R', F]] | F32: R' F2 R S R' F R S' R' F R | G32: =(len($F32)-len(SUBSTITUTE($F32,"R","")))+(len($F32)-len(SUBSTITUTE($F32,"L","")))+(len($F32)-len(SUBSTITUTE($F32,"U","")))+(len($F32)-len(SUBSTITUTE($F32,"D","")))+(len($F32)-len(SUBSTITUTE($F32,"F","")))+(len($F32)-len(SUBSTITUTE($F32,"B","")))+(len($F32)-len(SUBSTITUTE($F32,"M","")))+(len($F32)-len(SUBSTITUTE($F32,"S","")))+(len($F32)-len(SUBSTITUTE($F32,"E",""))) -> 11 | H32: =(len($F32)-len(SUBSTITUTE($F32,"R","")))+(len($F32)-len(SUBSTITUTE($F32,"L","")))+(len($F32)-len(SUBSTITUTE($F32,"U","")))+(len($F32)-len(SUBSTITUTE($F32,"D","")))+(len($F32)-len(SUBSTITUTE($F32,"F","")))+(len($F32)-len(SUBSTITUTE($F32,"B","")))+(len($F32)-len(SUBSTITUTE($F32,"M","")))+(len($F32)-len(SUBSTITUTE($F32,"S","")))+(len($F32)-len(SUBSTITUTE($F32,"E","")))+(len($F32)-len(SUBSTITUTE($F32,"2",""))) -> 12
B33: UL | C33: FL | D33: =VLOOKUP($B33,Letters!$C$29:$D$52,2,FALSE) & VLOOKUP($C33,Letters!$C$29:$D$52,2,FALSE) -> BJ | E33: [U M2 U', L'] | F33: U M2 U' L' U M2 U' L | G33: =(len($F33)-len(SUBSTITUTE($F33,"R","")))+(len($F33)-len(SUBSTITUTE($F33,"L","")))+(len($F33)-len(SUBSTITUTE($F33,"U","")))+(len($F33)-len(SUBSTITUTE($F33,"D","")))+(len($F33)-len(SUBSTITUTE($F33,"F","")))+(len($F33)-len(SUBSTITUTE($F33,"B","")))+(len($F33)-len(SUBSTITUTE($F33,"M","")))+(len($F33)-len(SUBSTITUTE($F33,"S","")))+(len($F33)-len(SUBSTITUTE($F33,"E",""))) -> 8 | H33: =(len($F33)-len(SUBSTITUTE($F33,"R","")))+(len($F33)-len(SUBSTITUTE($F33,"L","")))+(len($F33)-len(SUBSTITUTE($F33,"U","")))+(len($F33)-len(SUBSTITUTE($F33,"D","")))+(len($F33)-len(SUBSTITUTE($F33,"F","")))+(len($F33)-len(SUBSTITUTE($F33,"B","")))+(len($F33)-len(SUBSTITUTE($F33,"M","")))+(len($F33)-len(SUBSTITUTE($F33,"S","")))+(len($F33)-len(SUBSTITUTE($F33,"E","")))+(len($F33)-len(SUBSTITUTE($F33,"2",""))) -> 10
B34: UL | C34: FU | D34: =VLOOKUP($B34,Letters!$C$29:$D$52,2,FALSE) & VLOOKUP($C34,Letters!$C$29:$D$52,2,FALSE) -> BK | E34: [Lw': [U' L U , M']] | F34: Lw' U' L U M' U' L' U Lw2 L' | G34: =(len($F34)-len(SUBSTITUTE($F34,"R","")))+(len($F34)-len(SUBSTITUTE($F34,"L","")))+(len($F34)-len(SUBSTITUTE($F34,"U","")))+(len($F34)-len(SUBSTITUTE($F34,"D","")))+(len($F34)-len(SUBSTITUTE($F34,"F","")))+(len($F34)-len(SUBSTITUTE($F34,"B","")))+(len($F34)-len(SUBSTITUTE($F34,"M","")))+(len($F34)-len(SUBSTITUTE($F34,"S","")))+(len($F34)-len(SUBSTITUTE($F34,"E",""))) -> 10 | H34: =(len($F34)-len(SUBSTITUTE($F34,"R","")))+(len($F34)-len(SUBSTITUTE($F34,"L","")))+(len($F34)-len(SUBSTITUTE($F34,"U","")))+(len($F34)-len(SUBSTITUTE($F34,"D","")))+(len($F34)-len(SUBSTITUTE($F34,"F","")))+(len($F34)-len(SUBSTITUTE($F34,"B","")))+(len($F34)-len(SUBSTITUTE($F34,"M","")))+(len($F34)-len(SUBSTITUTE($F34,"S","")))+(len($F34)-len(SUBSTITUTE($F34,"E","")))+(len($F34)-len(SUBSTITUTE($F34,"2",""))) -> 11
B35: UL | C35: FR | D35: =VLOOKUP($B35,Letters!$C$29:$D$52,2,FALSE) & VLOOKUP($C35,Letters!$C$29:$D$52,2,FALSE) -> BL | E35: [R U: [M', U2]] | F35: R U M' U2 M U R' | G35: =(len($F35)-len(SUBSTITUTE($F35,"R","")))+(len($F35)-len(SUBSTITUTE($F35,"L","")))+(len($F35)-len(SUBSTITUTE($F35,"U","")))+(len($F35)-len(SUBSTITUTE($F35,"D","")))+(len($F35)-len(SUBSTITUTE($F35,"F","")))+(len($F35)-len(SUBSTITUTE($F35,"B","")))+(len($F35)-len(SUBSTITUTE($F35,"M","")))+(len($F35)-len(SUBSTITUTE($F35,"S","")))+(len($F35)-len(SUBSTITUTE($F35,"E",""))) -> 7 | H35: =(len($F35)-len(SUBSTITUTE($F35,"R","")))+(len($F35)-len(SUBSTITUTE($F35,"L","")))+(len($F35)-len(SUBSTITUTE($F35,"U","")))+(len($F35)-len(SUBSTITUTE($F35,"D","")))+(len($F35)-len(SUBSTITUTE($F35,"F","")))+(len($F35)-len(SUBSTITUTE($F35,"B","")))+(len($F35)-len(SUBSTITUTE($F35,"M","")))+(len($F35)-len(SUBSTITUTE($F35,"S","")))+(len($F35)-len(SUBSTITUTE($F35,"E","")))+(len($F35)-len(SUBSTITUTE($F35,"2",""))) -> 8
B36: UL | C36: RD | D36: =VLOOKUP($B36,Letters!$C$29:$D$52,2,FALSE) & VLOOKUP($C36,Letters!$C$29:$D$52,2,FALSE) -> BM | E36: [R' Fw' R': [S', R2]] | F36: R' Fw' R' S' R2 S R' Fw R | G36: =(len($F36)-len(SUBSTITUTE($F36,"R","")))+(len($F36)-len(SUBSTITUTE($F36,"L","")))+(len($F36)-len(SUBSTITUTE($F36,"U","")))+(len($F36)-len(SUBSTITUTE($F36,"D","")))+(len($F36)-len(SUBSTITUTE($F36,"F","")))+(len($F36)-len(SUBSTITUTE($F36,"B","")))+(len($F36)-len(SUBSTITUTE($F36,"M","")))+(len($F36)-len(SUBSTITUTE($F36,"S","")))+(len($F36)-len(SUBSTITUTE($F36,"E",""))) -> 9 | H36: =(len($F36)-len(SUBSTITUTE($F36,"R","")))+(len($F36)-len(SUBSTITUTE($F36,"L","")))+(len($F36)-len(SUBSTITUTE($F36,"U","")))+(len($F36)-len(SUBSTITUTE($F36,"D","")))+(len($F36)-len(SUBSTITUTE($F36,"F","")))+(len($F36)-len(SUBSTITUTE($F36,"B","")))+(len($F36)-len(SUBSTITUTE($F36,"M","")))+(len($F36)-len(SUBSTITUTE($F36,"S","")))+(len($F36)-len(SUBSTITUTE($F36,"E","")))+(len($F36)-len(SUBSTITUTE($F36,"2",""))) -> 10
B37: UL | C37: RF | D37: =VLOOKUP($B37,Letters!$C$29:$D$52,2,FALSE) & VLOOKUP($C37,Letters!$C$29:$D$52,2,FALSE) -> BN | E37: [R S R', F'] | F37: R S R' F' R S' R' F | G37: =(len($F37)-len(SUBSTITUTE($F37,"R","")))+(len($F37)-len(SUBSTITUTE($F37,"L","")))+(len($F37)-len(SUBSTITUTE($F37,"U","")))+(len($F37)-len(SUBSTITUTE($F37,"D","")))+(len($F37)-len(SUBSTITUTE($F37,"F","")))+(len($F37)-len(SUBSTITUTE($F37,"B","")))+(len($F37)-len(SUBSTITUTE($F37,"M","")))+(len($F37)-len(SUBSTITUTE($F37,"S","")))+(len($F37)-len(SUBSTITUTE($F37,"E",""))) -> 8 | H37: =(len($F37)-len(SUBSTITUTE($F37,"R","")))+(len($F37)-len(SUBSTITUTE($F37,"L","")))+(len($F37)-len(SUBSTITUTE($F37,"U","")))+(len($F37)-len(SUBSTITUTE($F37,"D","")))+(len($F37)-len(SUBSTITUTE($F37,"F","")))+(len($F37)-len(SUBSTITUTE($F37,"B","")))+(len($F37)-len(SUBSTITUTE($F37,"M","")))+(len($F37)-len(SUBSTITUTE($F37,"S","")))+(len($F37)-len(SUBSTITUTE($F37,"E","")))+(len($F37)-len(SUBSTITUTE($F37,"2",""))) -> 8
